<?xml version="1.0" ?>
<robot name="EKBot">
  <joint name="EKBot__roller1w1_joint_rev" type="revolute">
    <parent link="EKBot__MainWheel1"/>
    <child link="EKBot__roller1w1"/>
    <origin rpy="-1.57159  0      -3.14158" xyz="-0.029  0     0"/>
    <axis xyz="0  0 -1"/>
    <limit effort="0.0" lower="-1e+16" upper="1e+16" velocity="0.0"/>
  </joint>
  <joint name="EKBot__roller2w1_joint_rev" type="revolute">
    <parent link="EKBot__MainWheel1"/>
    <child link="EKBot__roller2w1"/>
    <origin rpy="-1.57155000e+00  -2.30000000e-04   2.84239000e+00" xyz="-0.02771  0.00855  0"/>
    <axis xyz="0.29475  0      -0.95557"/>
    <limit effort="0.0" lower="-1e+16" upper="1e+16" velocity="0.0"/>
  </joint>
  <joint name="EKBot__roller3w1_joint_rev" type="revolute">
    <parent link="EKBot__MainWheel1"/>
    <child link="EKBot__roller3w1"/>
    <origin rpy="-1.57145000e+00  -4.50000000e-04   2.54319000e+00" xyz="-2.39600000e-02   1.63400000e-02   1.00000000e-05"/>
    <axis xyz="0.56331  0      -0.82624"/>
    <limit effort="0.0" lower="-1e+16" upper="1e+16" velocity="0.0"/>
  </joint>
  <joint name="EKBot__roller4w1_joint_rev" type="revolute">
    <parent link="EKBot__MainWheel1"/>
    <child link="EKBot__roller4w1"/>
    <origin rpy="-1.57129000e+00  -6.20000000e-04   2.24399000e+00" xyz="-1.80800000e-02   2.26700000e-02   1.00000000e-05"/>
    <axis xyz="0.78183  0      -0.62349"/>
    <limit effort="0.0" lower="-1e+16" upper="1e+16" velocity="0.0"/>
  </joint>
  <joint name="EKBot__roller5w1_joint_rev" type="revolute">
    <parent link="EKBot__MainWheel1"/>
    <child link="EKBot__roller5w1"/>
    <origin rpy="-1.57108000e+00  -7.40000000e-04   1.94479000e+00" xyz="-1.05900000e-02   2.70000000e-02   2.00000000e-05"/>
    <axis xyz="0.93087  0      -0.36534"/>
    <limit effort="0.0" lower="-1e+16" upper="1e+16" velocity="0.0"/>
  </joint>
  <joint name="EKBot__roller6w1_joint_rev" type="revolute">
    <parent link="EKBot__MainWheel1"/>
    <child link="EKBot__roller6w1"/>
    <origin rpy="-1.57085000e+00  -7.90000000e-04   1.64559000e+00" xyz="-2.16000000e-03   2.89200000e-02   2.00000000e-05"/>
    <axis xyz="0.9972   0      -0.07473"/>
    <limit effort="0.0" lower="-1e+16" upper="1e+16" velocity="0.0"/>
  </joint>
  <joint name="EKBot__roller7w1_joint_rev" type="revolute">
    <parent link="EKBot__MainWheel1"/>
    <child link="EKBot__roller7w1"/>
    <origin rpy="-1.57061000e+00  -7.70000000e-04   1.34639000e+00" xyz="6.45000000e-03   2.82700000e-02   2.00000000e-05"/>
    <axis xyz="0.97492  0       0.22252"/>
    <limit effort="0.0" lower="-1e+16" upper="1e+16" velocity="0.0"/>
  </joint>
  <joint name="EKBot__roller8w1_joint_rev" type="revolute">
    <parent link="EKBot__MainWheel1"/>
    <child link="EKBot__roller8w1"/>
    <origin rpy="-1.57039000e+00  -6.80000000e-04   1.04719000e+00" xyz="1.45000000e-02   2.51100000e-02   2.00000000e-05"/>
    <axis xyz="0.86602  0       0.5"/>
    <limit effort="0.0" lower="-1e+16" upper="1e+16" velocity="0.0"/>
  </joint>
  <joint name="EKBot__roller9w1_joint_rev" type="revolute">
    <parent link="EKBot__MainWheel1"/>
    <child link="EKBot__roller9w1"/>
    <origin rpy="-1.57021000e+00  -5.40000000e-04   7.47990000e-01" xyz="2.12500000e-02   1.97300000e-02   1.00000000e-05"/>
    <axis xyz="0.68017  0       0.73305"/>
    <limit effort="0.0" lower="-1e+16" upper="1e+16" velocity="0.0"/>
  </joint>
  <joint name="EKBot__roller10w1_joint_rev" type="revolute">
    <parent link="EKBot__MainWheel1"/>
    <child link="EKBot__roller10w1"/>
    <origin rpy="-1.57007000e+00  -3.40000000e-04   4.48790000e-01" xyz="2.61200000e-02   1.25800000e-02   1.00000000e-05"/>
    <axis xyz="0.43388  0       0.90097"/>
    <limit effort="0.0" lower="-1e+16" upper="1e+16" velocity="0.0"/>
  </joint>
  <joint name="EKBot__roller11w1_joint_rev" type="revolute">
    <parent link="EKBot__MainWheel1"/>
    <child link="EKBot__roller11w1"/>
    <origin rpy="-1.57000000e+00  -1.10000000e-04   1.49590000e-01" xyz="0.02867  0.00432  0"/>
    <axis xyz="0.14904  0       0.98883"/>
    <limit effort="0.0" lower="-1e+16" upper="1e+16" velocity="0.0"/>
  </joint>
  <joint name="EKBot__roller12w1_joint_rev" type="revolute">
    <parent link="EKBot__MainWheel1"/>
    <child link="EKBot__roller12w1"/>
    <origin rpy="-1.57000000e+00   1.20000000e-04  -1.49600000e-01" xyz="0.02867 -0.00432  0"/>
    <axis xyz="-0.14904  0       0.98883"/>
    <limit effort="0.0" lower="-1e+16" upper="1e+16" velocity="0.0"/>
  </joint>
  <joint name="EKBot__roller13w1_joint_rev" type="revolute">
    <parent link="EKBot__MainWheel1"/>
    <child link="EKBot__roller13w1"/>
    <origin rpy="-1.57008000e+00   3.40000000e-04  -4.48800000e-01" xyz="2.61200000e-02  -1.25800000e-02  -1.00000000e-05"/>
    <axis xyz="-0.43388  0       0.90096"/>
    <limit effort="0.0" lower="-1e+16" upper="1e+16" velocity="0.0"/>
  </joint>
  <joint name="EKBot__roller14w1_joint_rev" type="revolute">
    <parent link="EKBot__MainWheel1"/>
    <child link="EKBot__roller14w1"/>
    <origin rpy="-1.57021000e+00   5.40000000e-04  -7.48000000e-01" xyz="2.12500000e-02  -1.97300000e-02  -1.00000000e-05"/>
    <axis xyz="-0.68017  0       0.73304"/>
    <limit effort="0.0" lower="-1e+16" upper="1e+16" velocity="0.0"/>
  </joint>
  <joint name="EKBot__roller15w1_joint_rev" type="revolute">
    <parent link="EKBot__MainWheel1"/>
    <child link="EKBot__roller15w1"/>
    <origin rpy="-1.57040000e+00   6.90000000e-04  -1.04719000e+00" xyz="1.45000000e-02  -2.51100000e-02  -2.00000000e-05"/>
    <axis xyz="-0.86602  0       0.5"/>
    <limit effort="0.0" lower="-1e+16" upper="1e+16" velocity="0.0"/>
  </joint>
  <joint name="EKBot__roller16w1_joint_rev" type="revolute">
    <parent link="EKBot__MainWheel1"/>
    <child link="EKBot__roller16w1"/>
    <origin rpy="-1.57062000e+00   7.70000000e-04  -1.34639000e+00" xyz="6.45000000e-03  -2.82700000e-02  -2.00000000e-05"/>
    <axis xyz="-0.97492  0       0.22252"/>
    <limit effort="0.0" lower="-1e+16" upper="1e+16" velocity="0.0"/>
  </joint>
  <joint name="EKBot__roller17w1_joint_rev" type="revolute">
    <parent link="EKBot__MainWheel1"/>
    <child link="EKBot__roller17w1"/>
    <origin rpy="-1.57085000e+00   7.90000000e-04  -1.64559000e+00" xyz="-2.16000000e-03  -2.89200000e-02  -2.00000000e-05"/>
    <axis xyz="-0.9972   0      -0.07472"/>
    <limit effort="0.0" lower="-1e+16" upper="1e+16" velocity="0.0"/>
  </joint>
  <joint name="EKBot__roller18w1_joint_rev" type="revolute">
    <parent link="EKBot__MainWheel1"/>
    <child link="EKBot__roller18w1"/>
    <origin rpy="-1.57109000e+00   7.40000000e-04  -1.94479000e+00" xyz="-1.05900000e-02  -2.70000000e-02  -2.00000000e-05"/>
    <axis xyz="-0.93087  0      -0.36533"/>
    <limit effort="0.0" lower="-1e+16" upper="1e+16" velocity="0.0"/>
  </joint>
  <joint name="EKBot__roller19w1_joint_rev" type="revolute">
    <parent link="EKBot__MainWheel1"/>
    <child link="EKBot__roller19w1"/>
    <origin rpy="-1.57129000e+00   6.20000000e-04  -2.24399000e+00" xyz="-1.80800000e-02  -2.26700000e-02  -1.00000000e-05"/>
    <axis xyz="-0.78183  0      -0.62348"/>
    <limit effort="0.0" lower="-1e+16" upper="1e+16" velocity="0.0"/>
  </joint>
  <joint name="EKBot__roller20w1_joint_rev" type="revolute">
    <parent link="EKBot__MainWheel1"/>
    <child link="EKBot__roller20w1"/>
    <origin rpy="-1.57145000e+00   4.40000000e-04  -2.54319000e+00" xyz="-2.39600000e-02  -1.63400000e-02  -1.00000000e-05"/>
    <axis xyz="-0.56332  0      -0.82623"/>
    <limit effort="0.0" lower="-1e+16" upper="1e+16" velocity="0.0"/>
  </joint>
  <joint name="EKBot__roller21w1_joint_rev" type="revolute">
    <parent link="EKBot__MainWheel1"/>
    <child link="EKBot__roller21w1"/>
    <origin rpy="-1.57155000e+00   2.30000000e-04  -2.84239000e+00" xyz="-0.02771 -0.00855  0"/>
    <axis xyz="-0.29475  0      -0.95557"/>
    <limit effort="0.0" lower="-1e+16" upper="1e+16" velocity="0.0"/>
  </joint>
  <joint name="EKBot__roller1w2_joint_rev" type="revolute">
    <parent link="EKBot__MainWheel2"/>
    <child link="EKBot__roller1w2"/>
    <origin rpy="-1.57  0    0" xyz="0.029  0     0"/>
    <axis xyz="0  0  1"/>
    <limit effort="0.0" lower="-1e+16" upper="1e+16" velocity="0.0"/>
  </joint>
  <joint name="EKBot__roller2w2_joint_rev" type="revolute">
    <parent link="EKBot__MainWheel2"/>
    <child link="EKBot__roller2w2"/>
    <origin rpy="-1.57003000e+00  -2.30000000e-04   2.99190000e-01" xyz="0.02771  0.00855  0"/>
    <axis xyz="0.29475  0       0.95557"/>
    <limit effort="0.0" lower="-1e+16" upper="1e+16" velocity="0.0"/>
  </joint>
  <joint name="EKBot__roller3w2_joint_rev" type="revolute">
    <parent link="EKBot__MainWheel2"/>
    <child link="EKBot__roller3w2"/>
    <origin rpy="-1.57013000e+00  -4.40000000e-04   5.98390000e-01" xyz="2.39600000e-02   1.63400000e-02   1.00000000e-05"/>
    <axis xyz="0.56331  0       0.82624"/>
    <limit effort="0.0" lower="-1e+16" upper="1e+16" velocity="0.0"/>
  </joint>
  <joint name="EKBot__roller4w2_joint_rev" type="revolute">
    <parent link="EKBot__MainWheel2"/>
    <child link="EKBot__roller4w2"/>
    <origin rpy="-1.57030000e+00  -6.20000000e-04   8.97590000e-01" xyz="1.80800000e-02   2.26700000e-02   1.00000000e-05"/>
    <axis xyz="0.78183  0       0.62349"/>
    <limit effort="0.0" lower="-1e+16" upper="1e+16" velocity="0.0"/>
  </joint>
  <joint name="EKBot__roller5w2_joint_rev" type="revolute">
    <parent link="EKBot__MainWheel2"/>
    <child link="EKBot__roller5w2"/>
    <origin rpy="-1.57050000e+00  -7.40000000e-04   1.19679000e+00" xyz="1.05900000e-02   2.70000000e-02   2.00000000e-05"/>
    <axis xyz="0.93087  0       0.36534"/>
    <limit effort="0.0" lower="-1e+16" upper="1e+16" velocity="0.0"/>
  </joint>
  <joint name="EKBot__roller6w2_joint_rev" type="revolute">
    <parent link="EKBot__MainWheel2"/>
    <child link="EKBot__roller6w2"/>
    <origin rpy="-1.57073000e+00  -7.90000000e-04   1.49599000e+00" xyz="2.16000000e-03   2.89200000e-02   2.00000000e-05"/>
    <axis xyz="0.9972   0       0.07473"/>
    <limit effort="0.0" lower="-1e+16" upper="1e+16" velocity="0.0"/>
  </joint>
  <joint name="EKBot__roller7w2_joint_rev" type="revolute">
    <parent link="EKBot__MainWheel2"/>
    <child link="EKBot__roller7w2"/>
    <origin rpy="-1.57097000e+00  -7.70000000e-04   1.79519000e+00" xyz="-6.45000000e-03   2.82700000e-02   2.00000000e-05"/>
    <axis xyz="0.97492  0      -0.22252"/>
    <limit effort="0.0" lower="-1e+16" upper="1e+16" velocity="0.0"/>
  </joint>
  <joint name="EKBot__roller8w2_joint_rev" type="revolute">
    <parent link="EKBot__MainWheel2"/>
    <child link="EKBot__roller8w2"/>
    <origin rpy="-1.57119000e+00  -6.90000000e-04   2.09439000e+00" xyz="-1.45000000e-02   2.51100000e-02   2.00000000e-05"/>
    <axis xyz="0.86602  0      -0.5"/>
    <limit effort="0.0" lower="-1e+16" upper="1e+16" velocity="0.0"/>
  </joint>
  <joint name="EKBot__roller9w2_joint_rev" type="revolute">
    <parent link="EKBot__MainWheel2"/>
    <child link="EKBot__roller9w2"/>
    <origin rpy="-1.57138000e+00  -5.40000000e-04   2.39359000e+00" xyz="-2.12500000e-02   1.97300000e-02   1.00000000e-05"/>
    <axis xyz="0.68017  0      -0.73305"/>
    <limit effort="0.0" lower="-1e+16" upper="1e+16" velocity="0.0"/>
  </joint>
  <joint name="EKBot__roller10w2_joint_rev" type="revolute">
    <parent link="EKBot__MainWheel2"/>
    <child link="EKBot__roller10w2"/>
    <origin rpy="-1.57151000e+00  -3.40000000e-04   2.69279000e+00" xyz="-2.61200000e-02   1.25800000e-02   1.00000000e-05"/>
    <axis xyz="0.43388  0      -0.90097"/>
    <limit effort="0.0" lower="-1e+16" upper="1e+16" velocity="0.0"/>
  </joint>
  <joint name="EKBot__roller11w2_joint_rev" type="revolute">
    <parent link="EKBot__MainWheel2"/>
    <child link="EKBot__roller11w2"/>
    <origin rpy="-1.57158000e+00  -1.10000000e-04   2.99199000e+00" xyz="-0.02867  0.00432  0"/>
    <axis xyz="0.14904  0      -0.98883"/>
    <limit effort="0.0" lower="-1e+16" upper="1e+16" velocity="0.0"/>
  </joint>
  <joint name="EKBot__roller12w2_joint_rev" type="revolute">
    <parent link="EKBot__MainWheel2"/>
    <child link="EKBot__roller12w2"/>
    <origin rpy="-1.57158000e+00   1.10000000e-04  -2.99199000e+00" xyz="-0.02867 -0.00432  0"/>
    <axis xyz="-0.14904  0      -0.98883"/>
    <limit effort="0.0" lower="-1e+16" upper="1e+16" velocity="0.0"/>
  </joint>
  <joint name="EKBot__roller13w2_joint_rev" type="revolute">
    <parent link="EKBot__MainWheel2"/>
    <child link="EKBot__roller13w2"/>
    <origin rpy="-1.57151000e+00   3.40000000e-04  -2.69279000e+00" xyz="-2.61200000e-02  -1.25800000e-02  -1.00000000e-05"/>
    <axis xyz="-0.43388  0      -0.90096"/>
    <limit effort="0.0" lower="-1e+16" upper="1e+16" velocity="0.0"/>
  </joint>
  <joint name="EKBot__roller14w2_joint_rev" type="revolute">
    <parent link="EKBot__MainWheel2"/>
    <child link="EKBot__roller14w2"/>
    <origin rpy="-1.57138000e+00   5.40000000e-04  -2.39359000e+00" xyz="-2.12500000e-02  -1.97300000e-02  -1.00000000e-05"/>
    <axis xyz="-0.68017  0      -0.73304"/>
    <limit effort="0.0" lower="-1e+16" upper="1e+16" velocity="0.0"/>
  </joint>
  <joint name="EKBot__roller15w2_joint_rev" type="revolute">
    <parent link="EKBot__MainWheel2"/>
    <child link="EKBot__roller15w2"/>
    <origin rpy="-1.57119000e+00   6.90000000e-04  -2.09439000e+00" xyz="-1.45000000e-02  -2.51100000e-02  -2.00000000e-05"/>
    <axis xyz="-0.86602  0      -0.5"/>
    <limit effort="0.0" lower="-1e+16" upper="1e+16" velocity="0.0"/>
  </joint>
  <joint name="EKBot__roller16w2_joint_rev" type="revolute">
    <parent link="EKBot__MainWheel2"/>
    <child link="EKBot__roller16w2"/>
    <origin rpy="-1.57097000e+00   7.70000000e-04  -1.79520000e+00" xyz="-6.45000000e-03  -2.82700000e-02  -2.00000000e-05"/>
    <axis xyz="-0.97492  0      -0.22252"/>
    <limit effort="0.0" lower="-1e+16" upper="1e+16" velocity="0.0"/>
  </joint>
  <joint name="EKBot__roller17w2_joint_rev" type="revolute">
    <parent link="EKBot__MainWheel2"/>
    <child link="EKBot__roller17w2"/>
    <origin rpy="-1.57073000e+00   7.90000000e-04  -1.49600000e+00" xyz="2.16000000e-03  -2.89200000e-02  -2.00000000e-05"/>
    <axis xyz="-0.9972   0       0.07472"/>
    <limit effort="0.0" lower="-1e+16" upper="1e+16" velocity="0.0"/>
  </joint>
  <joint name="EKBot__roller18w2_joint_rev" type="revolute">
    <parent link="EKBot__MainWheel2"/>
    <child link="EKBot__roller18w2"/>
    <origin rpy="-1.57050000e+00   7.40000000e-04  -1.19680000e+00" xyz="1.05900000e-02  -2.70000000e-02  -2.00000000e-05"/>
    <axis xyz="-0.93087  0       0.36533"/>
    <limit effort="0.0" lower="-1e+16" upper="1e+16" velocity="0.0"/>
  </joint>
  <joint name="EKBot__roller19w2_joint_rev" type="revolute">
    <parent link="EKBot__MainWheel2"/>
    <child link="EKBot__roller19w2"/>
    <origin rpy="-1.57030000e+00   6.20000000e-04  -8.97600000e-01" xyz="1.80800000e-02  -2.26700000e-02  -1.00000000e-05"/>
    <axis xyz="-0.78183  0       0.62348"/>
    <limit effort="0.0" lower="-1e+16" upper="1e+16" velocity="0.0"/>
  </joint>
  <joint name="EKBot__roller20w2_joint_rev" type="revolute">
    <parent link="EKBot__MainWheel2"/>
    <child link="EKBot__roller20w2"/>
    <origin rpy="-1.57013000e+00   4.40000000e-04  -5.98400000e-01" xyz="2.39600000e-02  -1.63400000e-02  -1.00000000e-05"/>
    <axis xyz="-0.56332  0       0.82623"/>
    <limit effort="0.0" lower="-1e+16" upper="1e+16" velocity="0.0"/>
  </joint>
  <joint name="EKBot__roller21w2_joint_rev" type="revolute">
    <parent link="EKBot__MainWheel2"/>
    <child link="EKBot__roller21w2"/>
    <origin rpy="-1.57003000e+00   2.30000000e-04  -2.99200000e-01" xyz="0.02771 -0.00855  0"/>
    <axis xyz="-0.29475  0       0.95557"/>
    <limit effort="0.0" lower="-1e+16" upper="1e+16" velocity="0.0"/>
  </joint>
  <joint name="EKBot__roller1w3_joint_rev" type="revolute">
    <parent link="EKBot__MainWheel3"/>
    <child link="EKBot__roller1w3"/>
    <origin rpy="-1.57  0    0" xyz="0.02899  0       0"/>
    <axis xyz="0  0  1"/>
    <limit effort="0.0" lower="-1e+16" upper="1e+16" velocity="0.0"/>
  </joint>
  <joint name="EKBot__roller2w3_joint_rev" type="revolute">
    <parent link="EKBot__MainWheel3"/>
    <child link="EKBot__roller2w3"/>
    <origin rpy="-1.57003000e+00  -2.30000000e-04   2.99190000e-01" xyz="0.02771  0.00855  0"/>
    <axis xyz="0.29475  0       0.95557"/>
    <limit effort="0.0" lower="-1e+16" upper="1e+16" velocity="0.0"/>
  </joint>
  <joint name="EKBot__roller3w3_joint_rev" type="revolute">
    <parent link="EKBot__MainWheel3"/>
    <child link="EKBot__roller3w3"/>
    <origin rpy="-1.57013000e+00  -4.40000000e-04   5.98390000e-01" xyz="2.39600000e-02   1.63400000e-02   1.00000000e-05"/>
    <axis xyz="0.56331  0       0.82624"/>
    <limit effort="0.0" lower="-1e+16" upper="1e+16" velocity="0.0"/>
  </joint>
  <joint name="EKBot__roller4w3_joint_rev" type="revolute">
    <parent link="EKBot__MainWheel3"/>
    <child link="EKBot__roller4w3"/>
    <origin rpy="-1.57030000e+00  -6.20000000e-04   8.97590000e-01" xyz="1.80800000e-02   2.26700000e-02   1.00000000e-05"/>
    <axis xyz="0.78183  0       0.62349"/>
    <limit effort="0.0" lower="-1e+16" upper="1e+16" velocity="0.0"/>
  </joint>
  <joint name="EKBot__roller5w3_joint_rev" type="revolute">
    <parent link="EKBot__MainWheel3"/>
    <child link="EKBot__roller5w3"/>
    <origin rpy="-1.57050000e+00  -7.40000000e-04   1.19679000e+00" xyz="1.05900000e-02   2.70000000e-02   2.00000000e-05"/>
    <axis xyz="0.93087  0       0.36534"/>
    <limit effort="0.0" lower="-1e+16" upper="1e+16" velocity="0.0"/>
  </joint>
  <joint name="EKBot__roller6w3_joint_rev" type="revolute">
    <parent link="EKBot__MainWheel3"/>
    <child link="EKBot__roller6w3"/>
    <origin rpy="-1.57073000e+00  -7.90000000e-04   1.49599000e+00" xyz="2.16000000e-03   2.89200000e-02   2.00000000e-05"/>
    <axis xyz="0.9972   0       0.07473"/>
    <limit effort="0.0" lower="-1e+16" upper="1e+16" velocity="0.0"/>
  </joint>
  <joint name="EKBot__roller7w3_joint_rev" type="revolute">
    <parent link="EKBot__MainWheel3"/>
    <child link="EKBot__roller7w3"/>
    <origin rpy="-1.57097000e+00  -7.70000000e-04   1.79519000e+00" xyz="-6.45000000e-03   2.82700000e-02   2.00000000e-05"/>
    <axis xyz="0.97492  0      -0.22252"/>
    <limit effort="0.0" lower="-1e+16" upper="1e+16" velocity="0.0"/>
  </joint>
  <joint name="EKBot__roller8w3_joint_rev" type="revolute">
    <parent link="EKBot__MainWheel3"/>
    <child link="EKBot__roller8w3"/>
    <origin rpy="-1.57119000e+00  -6.90000000e-04   2.09439000e+00" xyz="-1.45000000e-02   2.51100000e-02   1.00000000e-05"/>
    <axis xyz="0.86602  0      -0.5"/>
    <limit effort="0.0" lower="-1e+16" upper="1e+16" velocity="0.0"/>
  </joint>
  <joint name="EKBot__roller9w3_joint_rev" type="revolute">
    <parent link="EKBot__MainWheel3"/>
    <child link="EKBot__roller9w3"/>
    <origin rpy="-1.57138000e+00  -5.40000000e-04   2.39359000e+00" xyz="-2.12500000e-02   1.97300000e-02   1.00000000e-05"/>
    <axis xyz="0.68017  0      -0.73305"/>
    <limit effort="0.0" lower="-1e+16" upper="1e+16" velocity="0.0"/>
  </joint>
  <joint name="EKBot__roller10w3_joint_rev" type="revolute">
    <parent link="EKBot__MainWheel3"/>
    <child link="EKBot__roller10w3"/>
    <origin rpy="-1.57151000e+00  -3.40000000e-04   2.69279000e+00" xyz="-2.61200000e-02   1.25800000e-02   1.00000000e-05"/>
    <axis xyz="0.43388  0      -0.90097"/>
    <limit effort="0.0" lower="-1e+16" upper="1e+16" velocity="0.0"/>
  </joint>
  <joint name="EKBot__roller11w3_joint_rev" type="revolute">
    <parent link="EKBot__MainWheel3"/>
    <child link="EKBot__roller11w3"/>
    <origin rpy="-1.57158000e+00  -1.10000000e-04   2.99199000e+00" xyz="-0.02867  0.00432  0"/>
    <axis xyz="0.14904  0      -0.98883"/>
    <limit effort="0.0" lower="-1e+16" upper="1e+16" velocity="0.0"/>
  </joint>
  <joint name="EKBot__roller12w3_joint_rev" type="revolute">
    <parent link="EKBot__MainWheel3"/>
    <child link="EKBot__roller12w3"/>
    <origin rpy="-1.57158000e+00   1.10000000e-04  -2.99199000e+00" xyz="-0.02867 -0.00432  0"/>
    <axis xyz="-0.14904  0      -0.98883"/>
    <limit effort="0.0" lower="-1e+16" upper="1e+16" velocity="0.0"/>
  </joint>
  <joint name="EKBot__roller13w3_joint_rev" type="revolute">
    <parent link="EKBot__MainWheel3"/>
    <child link="EKBot__roller13w3"/>
    <origin rpy="-1.57151000e+00   3.40000000e-04  -2.69279000e+00" xyz="-2.61200000e-02  -1.25800000e-02  -1.00000000e-05"/>
    <axis xyz="-0.43388  0      -0.90096"/>
    <limit effort="0.0" lower="-1e+16" upper="1e+16" velocity="0.0"/>
  </joint>
  <joint name="EKBot__roller14w3_joint_rev" type="revolute">
    <parent link="EKBot__MainWheel3"/>
    <child link="EKBot__roller14w3"/>
    <origin rpy="-1.57138000e+00   5.40000000e-04  -2.39359000e+00" xyz="-2.12500000e-02  -1.97300000e-02  -1.00000000e-05"/>
    <axis xyz="-0.68017  0      -0.73304"/>
    <limit effort="0.0" lower="-1e+16" upper="1e+16" velocity="0.0"/>
  </joint>
  <joint name="EKBot__roller15w3_joint_rev" type="revolute">
    <parent link="EKBot__MainWheel3"/>
    <child link="EKBot__roller15w3"/>
    <origin rpy="-1.57119000e+00   6.90000000e-04  -2.09439000e+00" xyz="-1.45000000e-02  -2.51100000e-02  -2.00000000e-05"/>
    <axis xyz="-0.86602  0      -0.5"/>
    <limit effort="0.0" lower="-1e+16" upper="1e+16" velocity="0.0"/>
  </joint>
  <joint name="EKBot__roller16w3_joint_rev" type="revolute">
    <parent link="EKBot__MainWheel3"/>
    <child link="EKBot__roller16w3"/>
    <origin rpy="-1.57097000e+00   7.70000000e-04  -1.79520000e+00" xyz="-6.45000000e-03  -2.82700000e-02  -2.00000000e-05"/>
    <axis xyz="-0.97492  0      -0.22252"/>
    <limit effort="0.0" lower="-1e+16" upper="1e+16" velocity="0.0"/>
  </joint>
  <joint name="EKBot__roller17w3_joint_rev" type="revolute">
    <parent link="EKBot__MainWheel3"/>
    <child link="EKBot__roller17w3"/>
    <origin rpy="-1.57073000e+00   7.90000000e-04  -1.49600000e+00" xyz="2.16000000e-03  -2.89200000e-02  -2.00000000e-05"/>
    <axis xyz="-0.9972   0       0.07472"/>
    <limit effort="0.0" lower="-1e+16" upper="1e+16" velocity="0.0"/>
  </joint>
  <joint name="EKBot__roller18w3_joint_rev" type="revolute">
    <parent link="EKBot__MainWheel3"/>
    <child link="EKBot__roller18w3"/>
    <origin rpy="-1.57050000e+00   7.40000000e-04  -1.19680000e+00" xyz="1.05900000e-02  -2.70000000e-02  -2.00000000e-05"/>
    <axis xyz="-0.93087  0       0.36533"/>
    <limit effort="0.0" lower="-1e+16" upper="1e+16" velocity="0.0"/>
  </joint>
  <joint name="EKBot__roller19w3_joint_rev" type="revolute">
    <parent link="EKBot__MainWheel3"/>
    <child link="EKBot__roller19w3"/>
    <origin rpy="-1.57030000e+00   6.20000000e-04  -8.97600000e-01" xyz="1.80800000e-02  -2.26700000e-02  -1.00000000e-05"/>
    <axis xyz="-0.78183  0       0.62348"/>
    <limit effort="0.0" lower="-1e+16" upper="1e+16" velocity="0.0"/>
  </joint>
  <joint name="EKBot__roller20w3_joint_rev" type="revolute">
    <parent link="EKBot__MainWheel3"/>
    <child link="EKBot__roller20w3"/>
    <origin rpy="-1.57013000e+00   4.40000000e-04  -5.98400000e-01" xyz="2.39600000e-02  -1.63400000e-02  -1.00000000e-05"/>
    <axis xyz="-0.56332  0       0.82623"/>
    <limit effort="0.0" lower="-1e+16" upper="1e+16" velocity="0.0"/>
  </joint>
  <joint name="EKBot__roller21w3_joint_rev" type="revolute">
    <parent link="EKBot__MainWheel3"/>
    <child link="EKBot__roller21w3"/>
    <origin rpy="-1.57003000e+00   2.30000000e-04  -2.99200000e-01" xyz="0.02771 -0.00855  0"/>
    <axis xyz="-0.29475  0       0.95557"/>
    <limit effort="0.0" lower="-1e+16" upper="1e+16" velocity="0.0"/>
  </joint>
  <joint name="EKBot__roller1w4_joint_rev" type="revolute">
    <parent link="EKBot__MainWheel4"/>
    <child link="EKBot__roller1w4"/>
    <origin rpy="-1.57  0    0" xyz="0.029  0     0"/>
    <axis xyz="0  0  1"/>
    <limit effort="0.0" lower="-1e+16" upper="1e+16" velocity="0.0"/>
  </joint>
  <joint name="EKBot__roller2w4_joint_rev" type="revolute">
    <parent link="EKBot__MainWheel4"/>
    <child link="EKBot__roller2w4"/>
    <origin rpy="-1.57003000e+00  -2.30000000e-04   2.99190000e-01" xyz="0.02771  0.00855  0"/>
    <axis xyz="0.29475  0       0.95557"/>
    <limit effort="0.0" lower="-1e+16" upper="1e+16" velocity="0.0"/>
  </joint>
  <joint name="EKBot__roller3w4_joint_rev" type="revolute">
    <parent link="EKBot__MainWheel4"/>
    <child link="EKBot__roller3w4"/>
    <origin rpy="-1.57013000e+00  -4.40000000e-04   5.98390000e-01" xyz="2.39600000e-02   1.63400000e-02   1.00000000e-05"/>
    <axis xyz="0.56331  0       0.82624"/>
    <limit effort="0.0" lower="-1e+16" upper="1e+16" velocity="0.0"/>
  </joint>
  <joint name="EKBot__roller4w4_joint_rev" type="revolute">
    <parent link="EKBot__MainWheel4"/>
    <child link="EKBot__roller4w4"/>
    <origin rpy="-1.57030000e+00  -6.20000000e-04   8.97590000e-01" xyz="1.80800000e-02   2.26700000e-02   1.00000000e-05"/>
    <axis xyz="0.78183  0       0.62349"/>
    <limit effort="0.0" lower="-1e+16" upper="1e+16" velocity="0.0"/>
  </joint>
  <joint name="EKBot__roller5w4_joint_rev" type="revolute">
    <parent link="EKBot__MainWheel4"/>
    <child link="EKBot__roller5w4"/>
    <origin rpy="-1.57050000e+00  -7.40000000e-04   1.19679000e+00" xyz="1.05900000e-02   2.70000000e-02   2.00000000e-05"/>
    <axis xyz="0.93087  0       0.36534"/>
    <limit effort="0.0" lower="-1e+16" upper="1e+16" velocity="0.0"/>
  </joint>
  <joint name="EKBot__roller6w4_joint_rev" type="revolute">
    <parent link="EKBot__MainWheel4"/>
    <child link="EKBot__roller6w4"/>
    <origin rpy="-1.57073000e+00  -7.90000000e-04   1.49599000e+00" xyz="2.16000000e-03   2.89200000e-02   2.00000000e-05"/>
    <axis xyz="0.9972   0       0.07473"/>
    <limit effort="0.0" lower="-1e+16" upper="1e+16" velocity="0.0"/>
  </joint>
  <joint name="EKBot__roller7w4_joint_rev" type="revolute">
    <parent link="EKBot__MainWheel4"/>
    <child link="EKBot__roller7w4"/>
    <origin rpy="-1.57097000e+00  -7.70000000e-04   1.79519000e+00" xyz="-6.45000000e-03   2.82700000e-02   2.00000000e-05"/>
    <axis xyz="0.97492  0      -0.22252"/>
    <limit effort="0.0" lower="-1e+16" upper="1e+16" velocity="0.0"/>
  </joint>
  <joint name="EKBot__roller8w4_joint_rev" type="revolute">
    <parent link="EKBot__MainWheel4"/>
    <child link="EKBot__roller8w4"/>
    <origin rpy="-1.57119000e+00  -6.90000000e-04   2.09439000e+00" xyz="-1.45000000e-02   2.51100000e-02   2.00000000e-05"/>
    <axis xyz="0.86602  0      -0.5"/>
    <limit effort="0.0" lower="-1e+16" upper="1e+16" velocity="0.0"/>
  </joint>
  <joint name="EKBot__roller9w4_joint_rev" type="revolute">
    <parent link="EKBot__MainWheel4"/>
    <child link="EKBot__roller9w4"/>
    <origin rpy="-1.57138000e+00  -5.40000000e-04   2.39359000e+00" xyz="-2.12500000e-02   1.97300000e-02   1.00000000e-05"/>
    <axis xyz="0.68017  0      -0.73305"/>
    <limit effort="0.0" lower="-1e+16" upper="1e+16" velocity="0.0"/>
  </joint>
  <joint name="EKBot__roller10w4_joint_rev" type="revolute">
    <parent link="EKBot__MainWheel4"/>
    <child link="EKBot__roller10w4"/>
    <origin rpy="-1.57151000e+00  -3.40000000e-04   2.69279000e+00" xyz="-2.61200000e-02   1.25800000e-02   1.00000000e-05"/>
    <axis xyz="0.43388  0      -0.90097"/>
    <limit effort="0.0" lower="-1e+16" upper="1e+16" velocity="0.0"/>
  </joint>
  <joint name="EKBot__roller11w4_joint_rev" type="revolute">
    <parent link="EKBot__MainWheel4"/>
    <child link="EKBot__roller11w4"/>
    <origin rpy="-1.57158000e+00  -1.10000000e-04   2.99199000e+00" xyz="-0.02867  0.00432  0"/>
    <axis xyz="0.14904  0      -0.98883"/>
    <limit effort="0.0" lower="-1e+16" upper="1e+16" velocity="0.0"/>
  </joint>
  <joint name="EKBot__roller12w4_joint_rev" type="revolute">
    <parent link="EKBot__MainWheel4"/>
    <child link="EKBot__roller12w4"/>
    <origin rpy="-1.57158000e+00   1.10000000e-04  -2.99199000e+00" xyz="-0.02867 -0.00432  0"/>
    <axis xyz="-0.14904  0      -0.98883"/>
    <limit effort="0.0" lower="-1e+16" upper="1e+16" velocity="0.0"/>
  </joint>
  <joint name="EKBot__roller13w4_joint_rev" type="revolute">
    <parent link="EKBot__MainWheel4"/>
    <child link="EKBot__roller13w4"/>
    <origin rpy="-1.57151000e+00   3.40000000e-04  -2.69279000e+00" xyz="-2.61200000e-02  -1.25800000e-02  -1.00000000e-05"/>
    <axis xyz="-0.43388  0      -0.90096"/>
    <limit effort="0.0" lower="-1e+16" upper="1e+16" velocity="0.0"/>
  </joint>
  <joint name="EKBot__roller14w4_joint_rev" type="revolute">
    <parent link="EKBot__MainWheel4"/>
    <child link="EKBot__roller14w4"/>
    <origin rpy="-1.57138000e+00   5.40000000e-04  -2.39359000e+00" xyz="-2.12500000e-02  -1.97300000e-02  -1.00000000e-05"/>
    <axis xyz="-0.68017  0      -0.73304"/>
    <limit effort="0.0" lower="-1e+16" upper="1e+16" velocity="0.0"/>
  </joint>
  <joint name="EKBot__roller15w4_joint_rev" type="revolute">
    <parent link="EKBot__MainWheel4"/>
    <child link="EKBot__roller15w4"/>
    <origin rpy="-1.57119000e+00   6.90000000e-04  -2.09439000e+00" xyz="-1.45000000e-02  -2.51100000e-02  -2.00000000e-05"/>
    <axis xyz="-0.86602  0      -0.5"/>
    <limit effort="0.0" lower="-1e+16" upper="1e+16" velocity="0.0"/>
  </joint>
  <joint name="EKBot__roller16w4_joint_rev" type="revolute">
    <parent link="EKBot__MainWheel4"/>
    <child link="EKBot__roller16w4"/>
    <origin rpy="-1.57097000e+00   7.70000000e-04  -1.79520000e+00" xyz="-6.45000000e-03  -2.82700000e-02  -2.00000000e-05"/>
    <axis xyz="-0.97492  0      -0.22252"/>
    <limit effort="0.0" lower="-1e+16" upper="1e+16" velocity="0.0"/>
  </joint>
  <joint name="EKBot__roller17w4_joint_rev" type="revolute">
    <parent link="EKBot__MainWheel4"/>
    <child link="EKBot__roller17w4"/>
    <origin rpy="-1.57073000e+00   7.90000000e-04  -1.49600000e+00" xyz="2.16000000e-03  -2.89200000e-02  -2.00000000e-05"/>
    <axis xyz="-0.9972   0       0.07472"/>
    <limit effort="0.0" lower="-1e+16" upper="1e+16" velocity="0.0"/>
  </joint>
  <joint name="EKBot__roller18w4_joint_rev" type="revolute">
    <parent link="EKBot__MainWheel4"/>
    <child link="EKBot__roller18w4"/>
    <origin rpy="-1.57050000e+00   7.40000000e-04  -1.19680000e+00" xyz="1.05900000e-02  -2.70000000e-02  -2.00000000e-05"/>
    <axis xyz="-0.93087  0       0.36533"/>
    <limit effort="0.0" lower="-1e+16" upper="1e+16" velocity="0.0"/>
  </joint>
  <joint name="EKBot__roller19w4_joint_rev" type="revolute">
    <parent link="EKBot__MainWheel4"/>
    <child link="EKBot__roller19w4"/>
    <origin rpy="-1.57030000e+00   6.20000000e-04  -8.97600000e-01" xyz="1.80800000e-02  -2.26700000e-02  -1.00000000e-05"/>
    <axis xyz="-0.78183  0       0.62348"/>
    <limit effort="0.0" lower="-1e+16" upper="1e+16" velocity="0.0"/>
  </joint>
  <joint name="EKBot__roller20w4_joint_rev" type="revolute">
    <parent link="EKBot__MainWheel4"/>
    <child link="EKBot__roller20w4"/>
    <origin rpy="-1.57013000e+00   4.40000000e-04  -5.98400000e-01" xyz="2.39600000e-02  -1.63400000e-02  -1.00000000e-05"/>
    <axis xyz="-0.56332  0       0.82623"/>
    <limit effort="0.0" lower="-1e+16" upper="1e+16" velocity="0.0"/>
  </joint>
  <joint name="EKBot__roller21w4_joint_rev" type="revolute">
    <parent link="EKBot__MainWheel4"/>
    <child link="EKBot__roller21w4"/>
    <origin rpy="-1.57003000e+00   2.30000000e-04  -2.99200000e-01" xyz="0.02771 -0.00855  0"/>
    <axis xyz="-0.29475  0       0.95557"/>
    <limit effort="0.0" lower="-1e+16" upper="1e+16" velocity="0.0"/>
  </joint>
  <joint name="EKBot__chassis_JOINT_1" type="revolute">
    <parent link="EKBot__chassis"/>
    <child link="EKBot__MainWheel1"/>
    <origin rpy="1.57     0      -2.51327" xyz="0.04996 -0.06876  0.04"/>
    <axis xyz="0.00000000e+00  -1.00000000e+00  -7.90000000e-04"/>
    <limit effort="-1.0" lower="-1.79769e+308" upper="1.79769e+308" velocity="-1.0"/>
  </joint>
  <joint name="EKBot__chassis_JOINT_2" type="revolute">
    <parent link="EKBot__chassis"/>
    <child link="EKBot__MainWheel2"/>
    <origin rpy="1.57     0      -0.62831" xyz="0.04996  0.06876  0.04"/>
    <axis xyz="0.00000000e+00  -1.00000000e+00  -7.90000000e-04"/>
    <limit effort="-1.0" lower="-1.79769e+308" upper="1.79769e+308" velocity="-1.0"/>
  </joint>
  <joint name="EKBot__chassis_JOINT_3" type="revolute">
    <parent link="EKBot__chassis"/>
    <child link="EKBot__MainWheel3"/>
    <origin rpy="1.57     0       0.83775" xyz="-0.06316  0.05687  0.04"/>
    <axis xyz="0.00000000e+00  -1.00000000e+00  -7.90000000e-04"/>
    <limit effort="-1.0" lower="-1.79769e+308" upper="1.79769e+308" velocity="-1.0"/>
  </joint>
  <joint name="EKBot__chassis_JOINT_4" type="revolute">
    <parent link="EKBot__chassis"/>
    <child link="EKBot__MainWheel4"/>
    <origin rpy="1.57     0       2.30383" xyz="-0.06316 -0.05687  0.04"/>
    <axis xyz="0.00000000e+00  -1.00000000e+00  -7.90000000e-04"/>
    <limit effort="-1.0" lower="-1.79769e+308" upper="1.79769e+308" velocity="-1.0"/>
  </joint>
  <link name="EKBot__chassis">
    <inertial>
      <mass value="2"/>
      <origin rpy="0  0  0" xyz="0    0    0.115"/>
      <inertia ixx="0" ixy="0" ixz="0" iyy="0" iyz="0" izz="0"/>
    </inertial>
    <collision name="EKBot__collision">
      <origin rpy="0  0  0" xyz="0   0   0.1"/>
      <geometry>
        <cylinder length="0.15" radius="0.075"/>
      </geometry>
    </collision>
    <visual name="EKBot__visual">
      <origin rpy="0  0  0" xyz="0   0   0.1"/>
      <geometry>
        <cylinder length="0.15" radius="0.08"/>
      </geometry>
    </visual>
  </link>
  <link name="EKBot__MainWheel1">
    <inertial>
      <mass value="0"/>
      <origin rpy="1.57 0 3.769911184" xyz="0.04996  -0.068766  0.04"/>
      <inertia ixx="0" ixy="0" ixz="0" iyy="0" iyz="0" izz="0"/>
    </inertial>
    <collision name="EKBot__collision">
      <origin rpy="0  0  0" xyz="0  0  0"/>
      <geometry>
        <cylinder length="0.013" radius="0.034"/>
      </geometry>
    </collision>
    <visual name="EKBot__visual">
      <origin rpy="0  0  0" xyz="0  0  0"/>
      <geometry>
        <cylinder length="0.013" radius="0.034"/>
      </geometry>
    </visual>
  </link>
  <link name="EKBot__roller1w1">
    <inertial>
      <mass value="0"/>
      <origin rpy="0  0  0" xyz="0  0  0"/>
      <inertia ixx="0" ixy="0" ixz="0" iyy="0" iyz="0" izz="0"/>
    </inertial>
    <collision name="EKBot__collision">
      <origin rpy="0  0  0" xyz="0  0  0"/>
      <geometry>
        <cylinder length="0.004" radius="0.006"/>
      </geometry>
    </collision>
    <visual name="EKBot__visual">
      <origin rpy="0  0  0" xyz="0  0  0"/>
      <geometry>
        <cylinder length="0.004" radius="0.006"/>
      </geometry>
    </visual>
  </link>
  <link name="EKBot__roller2w1">
    <inertial>
      <mass value="0"/>
      <origin rpy="0  0  0" xyz="0  0  0"/>
      <inertia ixx="0" ixy="0" ixz="0" iyy="0" iyz="0" izz="0"/>
    </inertial>
    <collision name="EKBot__collision">
      <origin rpy="0  0  0" xyz="0  0  0"/>
      <geometry>
        <cylinder length="0.004" radius="0.006"/>
      </geometry>
    </collision>
    <visual name="EKBot__visual">
      <origin rpy="0  0  0" xyz="0  0  0"/>
      <geometry>
        <cylinder length="0.004" radius="0.006"/>
      </geometry>
    </visual>
  </link>
  <link name="EKBot__roller3w1">
    <inertial>
      <mass value="0"/>
      <origin rpy="0  0  0" xyz="0  0  0"/>
      <inertia ixx="0" ixy="0" ixz="0" iyy="0" iyz="0" izz="0"/>
    </inertial>
    <collision name="EKBot__collision">
      <origin rpy="0  0  0" xyz="0  0  0"/>
      <geometry>
        <cylinder length="0.004" radius="0.006"/>
      </geometry>
    </collision>
    <visual name="EKBot__visual">
      <origin rpy="0  0  0" xyz="0  0  0"/>
      <geometry>
        <cylinder length="0.004" radius="0.006"/>
      </geometry>
    </visual>
  </link>
  <link name="EKBot__roller4w1">
    <inertial>
      <mass value="0"/>
      <origin rpy="0  0  0" xyz="0  0  0"/>
      <inertia ixx="0" ixy="0" ixz="0" iyy="0" iyz="0" izz="0"/>
    </inertial>
    <collision name="EKBot__collision">
      <origin rpy="0  0  0" xyz="0  0  0"/>
      <geometry>
        <cylinder length="0.004" radius="0.006"/>
      </geometry>
    </collision>
    <visual name="EKBot__visual">
      <origin rpy="0  0  0" xyz="0  0  0"/>
      <geometry>
        <cylinder length="0.004" radius="0.006"/>
      </geometry>
    </visual>
  </link>
  <link name="EKBot__roller5w1">
    <inertial>
      <mass value="0"/>
      <origin rpy="0  0  0" xyz="0  0  0"/>
      <inertia ixx="0" ixy="0" ixz="0" iyy="0" iyz="0" izz="0"/>
    </inertial>
    <collision name="EKBot__collision">
      <origin rpy="0  0  0" xyz="0  0  0"/>
      <geometry>
        <cylinder length="0.004" radius="0.006"/>
      </geometry>
    </collision>
    <visual name="EKBot__visual">
      <origin rpy="0  0  0" xyz="0  0  0"/>
      <geometry>
        <cylinder length="0.004" radius="0.006"/>
      </geometry>
    </visual>
  </link>
  <link name="EKBot__roller6w1">
    <inertial>
      <mass value="0"/>
      <origin rpy="0  0  0" xyz="0  0  0"/>
      <inertia ixx="0" ixy="0" ixz="0" iyy="0" iyz="0" izz="0"/>
    </inertial>
    <collision name="EKBot__collision">
      <origin rpy="0  0  0" xyz="0  0  0"/>
      <geometry>
        <cylinder length="0.004" radius="0.006"/>
      </geometry>
    </collision>
    <visual name="EKBot__visual">
      <origin rpy="0  0  0" xyz="0  0  0"/>
      <geometry>
        <cylinder length="0.004" radius="0.006"/>
      </geometry>
    </visual>
  </link>
  <link name="EKBot__roller7w1">
    <inertial>
      <mass value="0"/>
      <origin rpy="0  0  0" xyz="0  0  0"/>
      <inertia ixx="0" ixy="0" ixz="0" iyy="0" iyz="0" izz="0"/>
    </inertial>
    <collision name="EKBot__collision">
      <origin rpy="0  0  0" xyz="0  0  0"/>
      <geometry>
        <cylinder length="0.004" radius="0.006"/>
      </geometry>
    </collision>
    <visual name="EKBot__visual">
      <origin rpy="0  0  0" xyz="0  0  0"/>
      <geometry>
        <cylinder length="0.004" radius="0.006"/>
      </geometry>
    </visual>
  </link>
  <link name="EKBot__roller8w1">
    <inertial>
      <mass value="0"/>
      <origin rpy="0  0  0" xyz="0  0  0"/>
      <inertia ixx="0" ixy="0" ixz="0" iyy="0" iyz="0" izz="0"/>
    </inertial>
    <collision name="EKBot__collision">
      <origin rpy="0  0  0" xyz="0  0  0"/>
      <geometry>
        <cylinder length="0.004" radius="0.006"/>
      </geometry>
    </collision>
    <visual name="EKBot__visual">
      <origin rpy="0  0  0" xyz="0  0  0"/>
      <geometry>
        <cylinder length="0.004" radius="0.006"/>
      </geometry>
    </visual>
  </link>
  <link name="EKBot__roller9w1">
    <inertial>
      <mass value="0"/>
      <origin rpy="0  0  0" xyz="0  0  0"/>
      <inertia ixx="0" ixy="0" ixz="0" iyy="0" iyz="0" izz="0"/>
    </inertial>
    <collision name="EKBot__collision">
      <origin rpy="0  0  0" xyz="0  0  0"/>
      <geometry>
        <cylinder length="0.004" radius="0.006"/>
      </geometry>
    </collision>
    <visual name="EKBot__visual">
      <origin rpy="0  0  0" xyz="0  0  0"/>
      <geometry>
        <cylinder length="0.004" radius="0.006"/>
      </geometry>
    </visual>
  </link>
  <link name="EKBot__roller10w1">
    <inertial>
      <mass value="0"/>
      <origin rpy="0  0  0" xyz="0  0  0"/>
      <inertia ixx="0" ixy="0" ixz="0" iyy="0" iyz="0" izz="0"/>
    </inertial>
    <collision name="EKBot__collision">
      <origin rpy="0  0  0" xyz="0  0  0"/>
      <geometry>
        <cylinder length="0.004" radius="0.006"/>
      </geometry>
    </collision>
    <visual name="EKBot__visual">
      <origin rpy="0  0  0" xyz="0  0  0"/>
      <geometry>
        <cylinder length="0.004" radius="0.006"/>
      </geometry>
    </visual>
  </link>
  <link name="EKBot__roller11w1">
    <inertial>
      <mass value="0"/>
      <origin rpy="0  0  0" xyz="0  0  0"/>
      <inertia ixx="0" ixy="0" ixz="0" iyy="0" iyz="0" izz="0"/>
    </inertial>
    <collision name="EKBot__collision">
      <origin rpy="0  0  0" xyz="0  0  0"/>
      <geometry>
        <cylinder length="0.004" radius="0.006"/>
      </geometry>
    </collision>
    <visual name="EKBot__visual">
      <origin rpy="0  0  0" xyz="0  0  0"/>
      <geometry>
        <cylinder length="0.004" radius="0.006"/>
      </geometry>
    </visual>
  </link>
  <link name="EKBot__roller12w1">
    <inertial>
      <mass value="0"/>
      <origin rpy="0  0  0" xyz="0  0  0"/>
      <inertia ixx="0" ixy="0" ixz="0" iyy="0" iyz="0" izz="0"/>
    </inertial>
    <collision name="EKBot__collision">
      <origin rpy="0  0  0" xyz="0  0  0"/>
      <geometry>
        <cylinder length="0.004" radius="0.006"/>
      </geometry>
    </collision>
    <visual name="EKBot__visual">
      <origin rpy="0  0  0" xyz="0  0  0"/>
      <geometry>
        <cylinder length="0.004" radius="0.006"/>
      </geometry>
    </visual>
  </link>
  <link name="EKBot__roller13w1">
    <inertial>
      <mass value="0"/>
      <origin rpy="0  0  0" xyz="0  0  0"/>
      <inertia ixx="0" ixy="0" ixz="0" iyy="0" iyz="0" izz="0"/>
    </inertial>
    <collision name="EKBot__collision">
      <origin rpy="0  0  0" xyz="0  0  0"/>
      <geometry>
        <cylinder length="0.004" radius="0.006"/>
      </geometry>
    </collision>
    <visual name="EKBot__visual">
      <origin rpy="0  0  0" xyz="0  0  0"/>
      <geometry>
        <cylinder length="0.004" radius="0.006"/>
      </geometry>
    </visual>
  </link>
  <link name="EKBot__roller14w1">
    <inertial>
      <mass value="0"/>
      <origin rpy="0  0  0" xyz="0  0  0"/>
      <inertia ixx="0" ixy="0" ixz="0" iyy="0" iyz="0" izz="0"/>
    </inertial>
    <collision name="EKBot__collision">
      <origin rpy="0  0  0" xyz="0  0  0"/>
      <geometry>
        <cylinder length="0.004" radius="0.006"/>
      </geometry>
    </collision>
    <visual name="EKBot__visual">
      <origin rpy="0  0  0" xyz="0  0  0"/>
      <geometry>
        <cylinder length="0.004" radius="0.006"/>
      </geometry>
    </visual>
  </link>
  <link name="EKBot__roller15w1">
    <inertial>
      <mass value="0"/>
      <origin rpy="0  0  0" xyz="0  0  0"/>
      <inertia ixx="0" ixy="0" ixz="0" iyy="0" iyz="0" izz="0"/>
    </inertial>
    <collision name="EKBot__collision">
      <origin rpy="0  0  0" xyz="0  0  0"/>
      <geometry>
        <cylinder length="0.004" radius="0.006"/>
      </geometry>
    </collision>
    <visual name="EKBot__visual">
      <origin rpy="0  0  0" xyz="0  0  0"/>
      <geometry>
        <cylinder length="0.004" radius="0.006"/>
      </geometry>
    </visual>
  </link>
  <link name="EKBot__roller16w1">
    <inertial>
      <mass value="0"/>
      <origin rpy="0  0  0" xyz="0  0  0"/>
      <inertia ixx="0" ixy="0" ixz="0" iyy="0" iyz="0" izz="0"/>
    </inertial>
    <collision name="EKBot__collision">
      <origin rpy="0  0  0" xyz="0  0  0"/>
      <geometry>
        <cylinder length="0.004" radius="0.006"/>
      </geometry>
    </collision>
    <visual name="EKBot__visual">
      <origin rpy="0  0  0" xyz="0  0  0"/>
      <geometry>
        <cylinder length="0.004" radius="0.006"/>
      </geometry>
    </visual>
  </link>
  <link name="EKBot__roller17w1">
    <inertial>
      <mass value="0"/>
      <origin rpy="0  0  0" xyz="0  0  0"/>
      <inertia ixx="0" ixy="0" ixz="0" iyy="0" iyz="0" izz="0"/>
    </inertial>
    <collision name="EKBot__collision">
      <origin rpy="0  0  0" xyz="0  0  0"/>
      <geometry>
        <cylinder length="0.004" radius="0.006"/>
      </geometry>
    </collision>
    <visual name="EKBot__visual">
      <origin rpy="0  0  0" xyz="0  0  0"/>
      <geometry>
        <cylinder length="0.004" radius="0.006"/>
      </geometry>
    </visual>
  </link>
  <link name="EKBot__roller18w1">
    <inertial>
      <mass value="0"/>
      <origin rpy="0  0  0" xyz="0  0  0"/>
      <inertia ixx="0" ixy="0" ixz="0" iyy="0" iyz="0" izz="0"/>
    </inertial>
    <collision name="EKBot__collision">
      <origin rpy="0  0  0" xyz="0  0  0"/>
      <geometry>
        <cylinder length="0.004" radius="0.006"/>
      </geometry>
    </collision>
    <visual name="EKBot__visual">
      <origin rpy="0  0  0" xyz="0  0  0"/>
      <geometry>
        <cylinder length="0.004" radius="0.006"/>
      </geometry>
    </visual>
  </link>
  <link name="EKBot__roller19w1">
    <inertial>
      <mass value="0"/>
      <origin rpy="0  0  0" xyz="0  0  0"/>
      <inertia ixx="0" ixy="0" ixz="0" iyy="0" iyz="0" izz="0"/>
    </inertial>
    <collision name="EKBot__collision">
      <origin rpy="0  0  0" xyz="0  0  0"/>
      <geometry>
        <cylinder length="0.004" radius="0.006"/>
      </geometry>
    </collision>
    <visual name="EKBot__visual">
      <origin rpy="0  0  0" xyz="0  0  0"/>
      <geometry>
        <cylinder length="0.004" radius="0.006"/>
      </geometry>
    </visual>
  </link>
  <link name="EKBot__roller20w1">
    <inertial>
      <mass value="0"/>
      <origin rpy="0  0  0" xyz="0  0  0"/>
      <inertia ixx="0" ixy="0" ixz="0" iyy="0" iyz="0" izz="0"/>
    </inertial>
    <collision name="EKBot__collision">
      <origin rpy="0  0  0" xyz="0  0  0"/>
      <geometry>
        <cylinder length="0.004" radius="0.006"/>
      </geometry>
    </collision>
    <visual name="EKBot__visual">
      <origin rpy="0  0  0" xyz="0  0  0"/>
      <geometry>
        <cylinder length="0.004" radius="0.006"/>
      </geometry>
    </visual>
  </link>
  <link name="EKBot__roller21w1">
    <inertial>
      <mass value="0"/>
      <origin rpy="0  0  0" xyz="0  0  0"/>
      <inertia ixx="0" ixy="0" ixz="0" iyy="0" iyz="0" izz="0"/>
    </inertial>
    <collision name="EKBot__collision">
      <origin rpy="0  0  0" xyz="0  0  0"/>
      <geometry>
        <cylinder length="0.004" radius="0.006"/>
      </geometry>
    </collision>
    <visual name="EKBot__visual">
      <origin rpy="0  0  0" xyz="0  0  0"/>
      <geometry>
        <cylinder length="0.004" radius="0.006"/>
      </geometry>
    </visual>
  </link>
  <link name="EKBot__MainWheel2">
    <inertial>
      <mass value="0"/>
      <origin rpy="0  0  0" xyz="0  0  0"/>
      <inertia ixx="0" ixy="0" ixz="0" iyy="0" iyz="0" izz="0"/>
    </inertial>
    <collision name="EKBot__collision">
      <origin rpy="0  0  0" xyz="0  0  0"/>
      <geometry>
        <cylinder length="0.013" radius="0.034"/>
      </geometry>
    </collision>
    <visual name="EKBot__visual">
      <origin rpy="0  0  0" xyz="0  0  0"/>
      <geometry>
        <cylinder length="0.013" radius="0.034"/>
      </geometry>
    </visual>
  </link>
  <link name="EKBot__roller1w2">
    <inertial>
      <mass value="0"/>
      <origin rpy="0  0  0" xyz="0  0  0"/>
      <inertia ixx="0" ixy="0" ixz="0" iyy="0" iyz="0" izz="0"/>
    </inertial>
    <collision name="EKBot__collision">
      <origin rpy="0  0  0" xyz="0  0  0"/>
      <geometry>
        <cylinder length="0.004" radius="0.006"/>
      </geometry>
    </collision>
    <visual name="EKBot__visual">
      <origin rpy="0  0  0" xyz="0  0  0"/>
      <geometry>
        <cylinder length="0.004" radius="0.006"/>
      </geometry>
    </visual>
  </link>
  <link name="EKBot__roller2w2">
    <inertial>
      <mass value="0"/>
      <origin rpy="0  0  0" xyz="0  0  0"/>
      <inertia ixx="0" ixy="0" ixz="0" iyy="0" iyz="0" izz="0"/>
    </inertial>
    <collision name="EKBot__collision">
      <origin rpy="0  0  0" xyz="0  0  0"/>
      <geometry>
        <cylinder length="0.004" radius="0.006"/>
      </geometry>
    </collision>
    <visual name="EKBot__visual">
      <origin rpy="0  0  0" xyz="0  0  0"/>
      <geometry>
        <cylinder length="0.004" radius="0.006"/>
      </geometry>
    </visual>
  </link>
  <link name="EKBot__roller3w2">
    <inertial>
      <mass value="0"/>
      <origin rpy="0  0  0" xyz="0  0  0"/>
      <inertia ixx="0" ixy="0" ixz="0" iyy="0" iyz="0" izz="0"/>
    </inertial>
    <collision name="EKBot__collision">
      <origin rpy="0  0  0" xyz="0  0  0"/>
      <geometry>
        <cylinder length="0.004" radius="0.006"/>
      </geometry>
    </collision>
    <visual name="EKBot__visual">
      <origin rpy="0  0  0" xyz="0  0  0"/>
      <geometry>
        <cylinder length="0.004" radius="0.006"/>
      </geometry>
    </visual>
  </link>
  <link name="EKBot__roller4w2">
    <inertial>
      <mass value="0"/>
      <origin rpy="0  0  0" xyz="0  0  0"/>
      <inertia ixx="0" ixy="0" ixz="0" iyy="0" iyz="0" izz="0"/>
    </inertial>
    <collision name="EKBot__collision">
      <origin rpy="0  0  0" xyz="0  0  0"/>
      <geometry>
        <cylinder length="0.004" radius="0.006"/>
      </geometry>
    </collision>
    <visual name="EKBot__visual">
      <origin rpy="0  0  0" xyz="0  0  0"/>
      <geometry>
        <cylinder length="0.004" radius="0.006"/>
      </geometry>
    </visual>
  </link>
  <link name="EKBot__roller5w2">
    <inertial>
      <mass value="0"/>
      <origin rpy="0  0  0" xyz="0  0  0"/>
      <inertia ixx="0" ixy="0" ixz="0" iyy="0" iyz="0" izz="0"/>
    </inertial>
    <collision name="EKBot__collision">
      <origin rpy="0  0  0" xyz="0  0  0"/>
      <geometry>
        <cylinder length="0.004" radius="0.006"/>
      </geometry>
    </collision>
    <visual name="EKBot__visual">
      <origin rpy="0  0  0" xyz="0  0  0"/>
      <geometry>
        <cylinder length="0.004" radius="0.006"/>
      </geometry>
    </visual>
  </link>
  <link name="EKBot__roller6w2">
    <inertial>
      <mass value="0"/>
      <origin rpy="0  0  0" xyz="0  0  0"/>
      <inertia ixx="0" ixy="0" ixz="0" iyy="0" iyz="0" izz="0"/>
    </inertial>
    <collision name="EKBot__collision">
      <origin rpy="0  0  0" xyz="0  0  0"/>
      <geometry>
        <cylinder length="0.004" radius="0.006"/>
      </geometry>
    </collision>
    <visual name="EKBot__visual">
      <origin rpy="0  0  0" xyz="0  0  0"/>
      <geometry>
        <cylinder length="0.004" radius="0.006"/>
      </geometry>
    </visual>
  </link>
  <link name="EKBot__roller7w2">
    <inertial>
      <mass value="0"/>
      <origin rpy="0  0  0" xyz="0  0  0"/>
      <inertia ixx="0" ixy="0" ixz="0" iyy="0" iyz="0" izz="0"/>
    </inertial>
    <collision name="EKBot__collision">
      <origin rpy="0  0  0" xyz="0  0  0"/>
      <geometry>
        <cylinder length="0.004" radius="0.006"/>
      </geometry>
    </collision>
    <visual name="EKBot__visual">
      <origin rpy="0  0  0" xyz="0  0  0"/>
      <geometry>
        <cylinder length="0.004" radius="0.006"/>
      </geometry>
    </visual>
  </link>
  <link name="EKBot__roller8w2">
    <inertial>
      <mass value="0"/>
      <origin rpy="0  0  0" xyz="0  0  0"/>
      <inertia ixx="0" ixy="0" ixz="0" iyy="0" iyz="0" izz="0"/>
    </inertial>
    <collision name="EKBot__collision">
      <origin rpy="0  0  0" xyz="0  0  0"/>
      <geometry>
        <cylinder length="0.004" radius="0.006"/>
      </geometry>
    </collision>
    <visual name="EKBot__visual">
      <origin rpy="0  0  0" xyz="0  0  0"/>
      <geometry>
        <cylinder length="0.004" radius="0.006"/>
      </geometry>
    </visual>
  </link>
  <link name="EKBot__roller9w2">
    <inertial>
      <mass value="0"/>
      <origin rpy="0  0  0" xyz="0  0  0"/>
      <inertia ixx="0" ixy="0" ixz="0" iyy="0" iyz="0" izz="0"/>
    </inertial>
    <collision name="EKBot__collision">
      <origin rpy="0  0  0" xyz="0  0  0"/>
      <geometry>
        <cylinder length="0.004" radius="0.006"/>
      </geometry>
    </collision>
    <visual name="EKBot__visual">
      <origin rpy="0  0  0" xyz="0  0  0"/>
      <geometry>
        <cylinder length="0.004" radius="0.006"/>
      </geometry>
    </visual>
  </link>
  <link name="EKBot__roller10w2">
    <inertial>
      <mass value="0"/>
      <origin rpy="0  0  0" xyz="0  0  0"/>
      <inertia ixx="0" ixy="0" ixz="0" iyy="0" iyz="0" izz="0"/>
    </inertial>
    <collision name="EKBot__collision">
      <origin rpy="0  0  0" xyz="0  0  0"/>
      <geometry>
        <cylinder length="0.004" radius="0.006"/>
      </geometry>
    </collision>
    <visual name="EKBot__visual">
      <origin rpy="0  0  0" xyz="0  0  0"/>
      <geometry>
        <cylinder length="0.004" radius="0.006"/>
      </geometry>
    </visual>
  </link>
  <link name="EKBot__roller11w2">
    <inertial>
      <mass value="0"/>
      <origin rpy="0  0  0" xyz="0  0  0"/>
      <inertia ixx="0" ixy="0" ixz="0" iyy="0" iyz="0" izz="0"/>
    </inertial>
    <collision name="EKBot__collision">
      <origin rpy="0  0  0" xyz="0  0  0"/>
      <geometry>
        <cylinder length="0.004" radius="0.006"/>
      </geometry>
    </collision>
    <visual name="EKBot__visual">
      <origin rpy="0  0  0" xyz="0  0  0"/>
      <geometry>
        <cylinder length="0.004" radius="0.006"/>
      </geometry>
    </visual>
  </link>
  <link name="EKBot__roller12w2">
    <inertial>
      <mass value="0"/>
      <origin rpy="0  0  0" xyz="0  0  0"/>
      <inertia ixx="0" ixy="0" ixz="0" iyy="0" iyz="0" izz="0"/>
    </inertial>
    <collision name="EKBot__collision">
      <origin rpy="0  0  0" xyz="0  0  0"/>
      <geometry>
        <cylinder length="0.004" radius="0.006"/>
      </geometry>
    </collision>
    <visual name="EKBot__visual">
      <origin rpy="0  0  0" xyz="0  0  0"/>
      <geometry>
        <cylinder length="0.004" radius="0.006"/>
      </geometry>
    </visual>
  </link>
  <link name="EKBot__roller13w2">
    <inertial>
      <mass value="0"/>
      <origin rpy="0  0  0" xyz="0  0  0"/>
      <inertia ixx="0" ixy="0" ixz="0" iyy="0" iyz="0" izz="0"/>
    </inertial>
    <collision name="EKBot__collision">
      <origin rpy="0  0  0" xyz="0  0  0"/>
      <geometry>
        <cylinder length="0.004" radius="0.006"/>
      </geometry>
    </collision>
    <visual name="EKBot__visual">
      <origin rpy="0  0  0" xyz="0  0  0"/>
      <geometry>
        <cylinder length="0.004" radius="0.006"/>
      </geometry>
    </visual>
  </link>
  <link name="EKBot__roller14w2">
    <inertial>
      <mass value="0"/>
      <origin rpy="0  0  0" xyz="0  0  0"/>
      <inertia ixx="0" ixy="0" ixz="0" iyy="0" iyz="0" izz="0"/>
    </inertial>
    <collision name="EKBot__collision">
      <origin rpy="0  0  0" xyz="0  0  0"/>
      <geometry>
        <cylinder length="0.004" radius="0.006"/>
      </geometry>
    </collision>
    <visual name="EKBot__visual">
      <origin rpy="0  0  0" xyz="0  0  0"/>
      <geometry>
        <cylinder length="0.004" radius="0.006"/>
      </geometry>
    </visual>
  </link>
  <link name="EKBot__roller15w2">
    <inertial>
      <mass value="0"/>
      <origin rpy="0  0  0" xyz="0  0  0"/>
      <inertia ixx="0" ixy="0" ixz="0" iyy="0" iyz="0" izz="0"/>
    </inertial>
    <collision name="EKBot__collision">
      <origin rpy="0  0  0" xyz="0  0  0"/>
      <geometry>
        <cylinder length="0.004" radius="0.006"/>
      </geometry>
    </collision>
    <visual name="EKBot__visual">
      <origin rpy="0  0  0" xyz="0  0  0"/>
      <geometry>
        <cylinder length="0.004" radius="0.006"/>
      </geometry>
    </visual>
  </link>
  <link name="EKBot__roller16w2">
    <inertial>
      <mass value="0"/>
      <origin rpy="0  0  0" xyz="0  0  0"/>
      <inertia ixx="0" ixy="0" ixz="0" iyy="0" iyz="0" izz="0"/>
    </inertial>
    <collision name="EKBot__collision">
      <origin rpy="0  0  0" xyz="0  0  0"/>
      <geometry>
        <cylinder length="0.004" radius="0.006"/>
      </geometry>
    </collision>
    <visual name="EKBot__visual">
      <origin rpy="0  0  0" xyz="0  0  0"/>
      <geometry>
        <cylinder length="0.004" radius="0.006"/>
      </geometry>
    </visual>
  </link>
  <link name="EKBot__roller17w2">
    <inertial>
      <mass value="0"/>
      <origin rpy="0  0  0" xyz="0  0  0"/>
      <inertia ixx="0" ixy="0" ixz="0" iyy="0" iyz="0" izz="0"/>
    </inertial>
    <collision name="EKBot__collision">
      <origin rpy="0  0  0" xyz="0  0  0"/>
      <geometry>
        <cylinder length="0.004" radius="0.006"/>
      </geometry>
    </collision>
    <visual name="EKBot__visual">
      <origin rpy="0  0  0" xyz="0  0  0"/>
      <geometry>
        <cylinder length="0.004" radius="0.006"/>
      </geometry>
    </visual>
  </link>
  <link name="EKBot__roller18w2">
    <inertial>
      <mass value="0"/>
      <origin rpy="0  0  0" xyz="0  0  0"/>
      <inertia ixx="0" ixy="0" ixz="0" iyy="0" iyz="0" izz="0"/>
    </inertial>
    <collision name="EKBot__collision">
      <origin rpy="0  0  0" xyz="0  0  0"/>
      <geometry>
        <cylinder length="0.004" radius="0.006"/>
      </geometry>
    </collision>
    <visual name="EKBot__visual">
      <origin rpy="0  0  0" xyz="0  0  0"/>
      <geometry>
        <cylinder length="0.004" radius="0.006"/>
      </geometry>
    </visual>
  </link>
  <link name="EKBot__roller19w2">
    <inertial>
      <mass value="0"/>
      <origin rpy="0  0  0" xyz="0  0  0"/>
      <inertia ixx="0" ixy="0" ixz="0" iyy="0" iyz="0" izz="0"/>
    </inertial>
    <collision name="EKBot__collision">
      <origin rpy="0  0  0" xyz="0  0  0"/>
      <geometry>
        <cylinder length="0.004" radius="0.006"/>
      </geometry>
    </collision>
    <visual name="EKBot__visual">
      <origin rpy="0  0  0" xyz="0  0  0"/>
      <geometry>
        <cylinder length="0.004" radius="0.006"/>
      </geometry>
    </visual>
  </link>
  <link name="EKBot__roller20w2">
    <inertial>
      <mass value="0"/>
      <origin rpy="0  0  0" xyz="0  0  0"/>
      <inertia ixx="0" ixy="0" ixz="0" iyy="0" iyz="0" izz="0"/>
    </inertial>
    <collision name="EKBot__collision">
      <origin rpy="0  0  0" xyz="0  0  0"/>
      <geometry>
        <cylinder length="0.004" radius="0.006"/>
      </geometry>
    </collision>
    <visual name="EKBot__visual">
      <origin rpy="0  0  0" xyz="0  0  0"/>
      <geometry>
        <cylinder length="0.004" radius="0.006"/>
      </geometry>
    </visual>
  </link>
  <link name="EKBot__roller21w2">
    <inertial>
      <mass value="0"/>
      <origin rpy="0  0  0" xyz="0  0  0"/>
      <inertia ixx="0" ixy="0" ixz="0" iyy="0" iyz="0" izz="0"/>
    </inertial>
    <collision name="EKBot__collision">
      <origin rpy="0  0  0" xyz="0  0  0"/>
      <geometry>
        <cylinder length="0.004" radius="0.006"/>
      </geometry>
    </collision>
    <visual name="EKBot__visual">
      <origin rpy="0  0  0" xyz="0  0  0"/>
      <geometry>
        <cylinder length="0.004" radius="0.006"/>
      </geometry>
    </visual>
  </link>
  <link name="EKBot__MainWheel3">
    <inertial>
      <mass value="0"/>
      <origin rpy="0  0  0" xyz="0  0  0"/>
      <inertia ixx="0" ixy="0" ixz="0" iyy="0" iyz="0" izz="0"/>
    </inertial>
    <collision name="EKBot__collision">
      <origin rpy="0  0  0" xyz="0  0  0"/>
      <geometry>
        <cylinder length="0.013" radius="0.034"/>
      </geometry>
    </collision>
    <visual name="EKBot__visual">
      <origin rpy="0  0  0" xyz="0  0  0"/>
      <geometry>
        <cylinder length="0.013" radius="0.034"/>
      </geometry>
    </visual>
  </link>
  <link name="EKBot__roller1w3">
    <inertial>
      <mass value="0"/>
      <origin rpy="0  0  0" xyz="0  0  0"/>
      <inertia ixx="0" ixy="0" ixz="0" iyy="0" iyz="0" izz="0"/>
    </inertial>
    <collision name="EKBot__collision">
      <origin rpy="0  0  0" xyz="0  0  0"/>
      <geometry>
        <cylinder length="0.004" radius="0.006"/>
      </geometry>
    </collision>
    <visual name="EKBot__visual">
      <origin rpy="0  0  0" xyz="0  0  0"/>
      <geometry>
        <cylinder length="0.004" radius="0.006"/>
      </geometry>
    </visual>
  </link>
  <link name="EKBot__roller2w3">
    <inertial>
      <mass value="0"/>
      <origin rpy="0  0  0" xyz="0  0  0"/>
      <inertia ixx="0" ixy="0" ixz="0" iyy="0" iyz="0" izz="0"/>
    </inertial>
    <collision name="EKBot__collision">
      <origin rpy="0  0  0" xyz="0  0  0"/>
      <geometry>
        <cylinder length="0.004" radius="0.006"/>
      </geometry>
    </collision>
    <visual name="EKBot__visual">
      <origin rpy="0  0  0" xyz="0  0  0"/>
      <geometry>
        <cylinder length="0.004" radius="0.006"/>
      </geometry>
    </visual>
  </link>
  <link name="EKBot__roller3w3">
    <inertial>
      <mass value="0"/>
      <origin rpy="0  0  0" xyz="0  0  0"/>
      <inertia ixx="0" ixy="0" ixz="0" iyy="0" iyz="0" izz="0"/>
    </inertial>
    <collision name="EKBot__collision">
      <origin rpy="0  0  0" xyz="0  0  0"/>
      <geometry>
        <cylinder length="0.004" radius="0.006"/>
      </geometry>
    </collision>
    <visual name="EKBot__visual">
      <origin rpy="0  0  0" xyz="0  0  0"/>
      <geometry>
        <cylinder length="0.004" radius="0.006"/>
      </geometry>
    </visual>
  </link>
  <link name="EKBot__roller4w3">
    <inertial>
      <mass value="0"/>
      <origin rpy="0  0  0" xyz="0  0  0"/>
      <inertia ixx="0" ixy="0" ixz="0" iyy="0" iyz="0" izz="0"/>
    </inertial>
    <collision name="EKBot__collision">
      <origin rpy="0  0  0" xyz="0  0  0"/>
      <geometry>
        <cylinder length="0.004" radius="0.006"/>
      </geometry>
    </collision>
    <visual name="EKBot__visual">
      <origin rpy="0  0  0" xyz="0  0  0"/>
      <geometry>
        <cylinder length="0.004" radius="0.006"/>
      </geometry>
    </visual>
  </link>
  <link name="EKBot__roller5w3">
    <inertial>
      <mass value="0"/>
      <origin rpy="0  0  0" xyz="0  0  0"/>
      <inertia ixx="0" ixy="0" ixz="0" iyy="0" iyz="0" izz="0"/>
    </inertial>
    <collision name="EKBot__collision">
      <origin rpy="0  0  0" xyz="0  0  0"/>
      <geometry>
        <cylinder length="0.004" radius="0.006"/>
      </geometry>
    </collision>
    <visual name="EKBot__visual">
      <origin rpy="0  0  0" xyz="0  0  0"/>
      <geometry>
        <cylinder length="0.004" radius="0.006"/>
      </geometry>
    </visual>
  </link>
  <link name="EKBot__roller6w3">
    <inertial>
      <mass value="0"/>
      <origin rpy="0  0  0" xyz="0  0  0"/>
      <inertia ixx="0" ixy="0" ixz="0" iyy="0" iyz="0" izz="0"/>
    </inertial>
    <collision name="EKBot__collision">
      <origin rpy="0  0  0" xyz="0  0  0"/>
      <geometry>
        <cylinder length="0.004" radius="0.006"/>
      </geometry>
    </collision>
    <visual name="EKBot__visual">
      <origin rpy="0  0  0" xyz="0  0  0"/>
      <geometry>
        <cylinder length="0.004" radius="0.006"/>
      </geometry>
    </visual>
  </link>
  <link name="EKBot__roller7w3">
    <inertial>
      <mass value="0"/>
      <origin rpy="0  0  0" xyz="0  0  0"/>
      <inertia ixx="0" ixy="0" ixz="0" iyy="0" iyz="0" izz="0"/>
    </inertial>
    <collision name="EKBot__collision">
      <origin rpy="0  0  0" xyz="0  0  0"/>
      <geometry>
        <cylinder length="0.004" radius="0.006"/>
      </geometry>
    </collision>
    <visual name="EKBot__visual">
      <origin rpy="0  0  0" xyz="0  0  0"/>
      <geometry>
        <cylinder length="0.004" radius="0.006"/>
      </geometry>
    </visual>
  </link>
  <link name="EKBot__roller8w3">
    <inertial>
      <mass value="0"/>
      <origin rpy="0  0  0" xyz="0  0  0"/>
      <inertia ixx="0" ixy="0" ixz="0" iyy="0" iyz="0" izz="0"/>
    </inertial>
    <collision name="EKBot__collision">
      <origin rpy="0  0  0" xyz="0  0  0"/>
      <geometry>
        <cylinder length="0.004" radius="0.006"/>
      </geometry>
    </collision>
    <visual name="EKBot__visual">
      <origin rpy="0  0  0" xyz="0  0  0"/>
      <geometry>
        <cylinder length="0.004" radius="0.006"/>
      </geometry>
    </visual>
  </link>
  <link name="EKBot__roller9w3">
    <inertial>
      <mass value="0"/>
      <origin rpy="0  0  0" xyz="0  0  0"/>
      <inertia ixx="0" ixy="0" ixz="0" iyy="0" iyz="0" izz="0"/>
    </inertial>
    <collision name="EKBot__collision">
      <origin rpy="0  0  0" xyz="0  0  0"/>
      <geometry>
        <cylinder length="0.004" radius="0.006"/>
      </geometry>
    </collision>
    <visual name="EKBot__visual">
      <origin rpy="0  0  0" xyz="0  0  0"/>
      <geometry>
        <cylinder length="0.004" radius="0.006"/>
      </geometry>
    </visual>
  </link>
  <link name="EKBot__roller10w3">
    <inertial>
      <mass value="0"/>
      <origin rpy="0  0  0" xyz="0  0  0"/>
      <inertia ixx="0" ixy="0" ixz="0" iyy="0" iyz="0" izz="0"/>
    </inertial>
    <collision name="EKBot__collision">
      <origin rpy="0  0  0" xyz="0  0  0"/>
      <geometry>
        <cylinder length="0.004" radius="0.006"/>
      </geometry>
    </collision>
    <visual name="EKBot__visual">
      <origin rpy="0  0  0" xyz="0  0  0"/>
      <geometry>
        <cylinder length="0.004" radius="0.006"/>
      </geometry>
    </visual>
  </link>
  <link name="EKBot__roller11w3">
    <inertial>
      <mass value="0"/>
      <origin rpy="0  0  0" xyz="0  0  0"/>
      <inertia ixx="0" ixy="0" ixz="0" iyy="0" iyz="0" izz="0"/>
    </inertial>
    <collision name="EKBot__collision">
      <origin rpy="0  0  0" xyz="0  0  0"/>
      <geometry>
        <cylinder length="0.004" radius="0.006"/>
      </geometry>
    </collision>
    <visual name="EKBot__visual">
      <origin rpy="0  0  0" xyz="0  0  0"/>
      <geometry>
        <cylinder length="0.004" radius="0.006"/>
      </geometry>
    </visual>
  </link>
  <link name="EKBot__roller12w3">
    <inertial>
      <mass value="0"/>
      <origin rpy="0  0  0" xyz="0  0  0"/>
      <inertia ixx="0" ixy="0" ixz="0" iyy="0" iyz="0" izz="0"/>
    </inertial>
    <collision name="EKBot__collision">
      <origin rpy="0  0  0" xyz="0  0  0"/>
      <geometry>
        <cylinder length="0.004" radius="0.006"/>
      </geometry>
    </collision>
    <visual name="EKBot__visual">
      <origin rpy="0  0  0" xyz="0  0  0"/>
      <geometry>
        <cylinder length="0.004" radius="0.006"/>
      </geometry>
    </visual>
  </link>
  <link name="EKBot__roller13w3">
    <inertial>
      <mass value="0"/>
      <origin rpy="0  0  0" xyz="0  0  0"/>
      <inertia ixx="0" ixy="0" ixz="0" iyy="0" iyz="0" izz="0"/>
    </inertial>
    <collision name="EKBot__collision">
      <origin rpy="0  0  0" xyz="0  0  0"/>
      <geometry>
        <cylinder length="0.004" radius="0.006"/>
      </geometry>
    </collision>
    <visual name="EKBot__visual">
      <origin rpy="0  0  0" xyz="0  0  0"/>
      <geometry>
        <cylinder length="0.004" radius="0.006"/>
      </geometry>
    </visual>
  </link>
  <link name="EKBot__roller14w3">
    <inertial>
      <mass value="0"/>
      <origin rpy="0  0  0" xyz="0  0  0"/>
      <inertia ixx="0" ixy="0" ixz="0" iyy="0" iyz="0" izz="0"/>
    </inertial>
    <collision name="EKBot__collision">
      <origin rpy="0  0  0" xyz="0  0  0"/>
      <geometry>
        <cylinder length="0.004" radius="0.006"/>
      </geometry>
    </collision>
    <visual name="EKBot__visual">
      <origin rpy="0  0  0" xyz="0  0  0"/>
      <geometry>
        <cylinder length="0.004" radius="0.006"/>
      </geometry>
    </visual>
  </link>
  <link name="EKBot__roller15w3">
    <inertial>
      <mass value="0"/>
      <origin rpy="0  0  0" xyz="0  0  0"/>
      <inertia ixx="0" ixy="0" ixz="0" iyy="0" iyz="0" izz="0"/>
    </inertial>
    <collision name="EKBot__collision">
      <origin rpy="0  0  0" xyz="0  0  0"/>
      <geometry>
        <cylinder length="0.004" radius="0.006"/>
      </geometry>
    </collision>
    <visual name="EKBot__visual">
      <origin rpy="0  0  0" xyz="0  0  0"/>
      <geometry>
        <cylinder length="0.004" radius="0.006"/>
      </geometry>
    </visual>
  </link>
  <link name="EKBot__roller16w3">
    <inertial>
      <mass value="0"/>
      <origin rpy="0  0  0" xyz="0  0  0"/>
      <inertia ixx="0" ixy="0" ixz="0" iyy="0" iyz="0" izz="0"/>
    </inertial>
    <collision name="EKBot__collision">
      <origin rpy="0  0  0" xyz="0  0  0"/>
      <geometry>
        <cylinder length="0.004" radius="0.006"/>
      </geometry>
    </collision>
    <visual name="EKBot__visual">
      <origin rpy="0  0  0" xyz="0  0  0"/>
      <geometry>
        <cylinder length="0.004" radius="0.006"/>
      </geometry>
    </visual>
  </link>
  <link name="EKBot__roller17w3">
    <inertial>
      <mass value="0"/>
      <origin rpy="0  0  0" xyz="0  0  0"/>
      <inertia ixx="0" ixy="0" ixz="0" iyy="0" iyz="0" izz="0"/>
    </inertial>
    <collision name="EKBot__collision">
      <origin rpy="0  0  0" xyz="0  0  0"/>
      <geometry>
        <cylinder length="0.004" radius="0.006"/>
      </geometry>
    </collision>
    <visual name="EKBot__visual">
      <origin rpy="0  0  0" xyz="0  0  0"/>
      <geometry>
        <cylinder length="0.004" radius="0.006"/>
      </geometry>
    </visual>
  </link>
  <link name="EKBot__roller18w3">
    <inertial>
      <mass value="0"/>
      <origin rpy="0  0  0" xyz="0  0  0"/>
      <inertia ixx="0" ixy="0" ixz="0" iyy="0" iyz="0" izz="0"/>
    </inertial>
    <collision name="EKBot__collision">
      <origin rpy="0  0  0" xyz="0  0  0"/>
      <geometry>
        <cylinder length="0.004" radius="0.006"/>
      </geometry>
    </collision>
    <visual name="EKBot__visual">
      <origin rpy="0  0  0" xyz="0  0  0"/>
      <geometry>
        <cylinder length="0.004" radius="0.006"/>
      </geometry>
    </visual>
  </link>
  <link name="EKBot__roller19w3">
    <inertial>
      <mass value="0"/>
      <origin rpy="0  0  0" xyz="0  0  0"/>
      <inertia ixx="0" ixy="0" ixz="0" iyy="0" iyz="0" izz="0"/>
    </inertial>
    <collision name="EKBot__collision">
      <origin rpy="0  0  0" xyz="0  0  0"/>
      <geometry>
        <cylinder length="0.004" radius="0.006"/>
      </geometry>
    </collision>
    <visual name="EKBot__visual">
      <origin rpy="0  0  0" xyz="0  0  0"/>
      <geometry>
        <cylinder length="0.004" radius="0.006"/>
      </geometry>
    </visual>
  </link>
  <link name="EKBot__roller20w3">
    <inertial>
      <mass value="0"/>
      <origin rpy="0  0  0" xyz="0  0  0"/>
      <inertia ixx="0" ixy="0" ixz="0" iyy="0" iyz="0" izz="0"/>
    </inertial>
    <collision name="EKBot__collision">
      <origin rpy="0  0  0" xyz="0  0  0"/>
      <geometry>
        <cylinder length="0.004" radius="0.006"/>
      </geometry>
    </collision>
    <visual name="EKBot__visual">
      <origin rpy="0  0  0" xyz="0  0  0"/>
      <geometry>
        <cylinder length="0.004" radius="0.006"/>
      </geometry>
    </visual>
  </link>
  <link name="EKBot__roller21w3">
    <inertial>
      <mass value="0"/>
      <origin rpy="0  0  0" xyz="0  0  0"/>
      <inertia ixx="0" ixy="0" ixz="0" iyy="0" iyz="0" izz="0"/>
    </inertial>
    <collision name="EKBot__collision">
      <origin rpy="0  0  0" xyz="0  0  0"/>
      <geometry>
        <cylinder length="0.004" radius="0.006"/>
      </geometry>
    </collision>
    <visual name="EKBot__visual">
      <origin rpy="0  0  0" xyz="0  0  0"/>
      <geometry>
        <cylinder length="0.004" radius="0.006"/>
      </geometry>
    </visual>
  </link>
  <link name="EKBot__MainWheel4">
    <inertial>
      <mass value="0"/>
      <origin rpy="0  0  0" xyz="0  0  0"/>
      <inertia ixx="0" ixy="0" ixz="0" iyy="0" iyz="0" izz="0"/>
    </inertial>
    <collision name="EKBot__collision">
      <origin rpy="0  0  0" xyz="0  0  0"/>
      <geometry>
        <cylinder length="0.013" radius="0.034"/>
      </geometry>
    </collision>
    <visual name="EKBot__visual">
      <origin rpy="0  0  0" xyz="0  0  0"/>
      <geometry>
        <cylinder length="0.013" radius="0.034"/>
      </geometry>
    </visual>
  </link>
  <link name="EKBot__roller1w4">
    <inertial>
      <mass value="0"/>
      <origin rpy="0  0  0" xyz="0  0  0"/>
      <inertia ixx="0" ixy="0" ixz="0" iyy="0" iyz="0" izz="0"/>
    </inertial>
    <collision name="EKBot__collision">
      <origin rpy="0  0  0" xyz="0  0  0"/>
      <geometry>
        <cylinder length="0.004" radius="0.006"/>
      </geometry>
    </collision>
    <visual name="EKBot__visual">
      <origin rpy="0  0  0" xyz="0  0  0"/>
      <geometry>
        <cylinder length="0.004" radius="0.006"/>
      </geometry>
    </visual>
  </link>
  <link name="EKBot__roller2w4">
    <inertial>
      <mass value="0"/>
      <origin rpy="0  0  0" xyz="0  0  0"/>
      <inertia ixx="0" ixy="0" ixz="0" iyy="0" iyz="0" izz="0"/>
    </inertial>
    <collision name="EKBot__collision">
      <origin rpy="0  0  0" xyz="0  0  0"/>
      <geometry>
        <cylinder length="0.004" radius="0.006"/>
      </geometry>
    </collision>
    <visual name="EKBot__visual">
      <origin rpy="0  0  0" xyz="0  0  0"/>
      <geometry>
        <cylinder length="0.004" radius="0.006"/>
      </geometry>
    </visual>
  </link>
  <link name="EKBot__roller3w4">
    <inertial>
      <mass value="0"/>
      <origin rpy="0  0  0" xyz="0  0  0"/>
      <inertia ixx="0" ixy="0" ixz="0" iyy="0" iyz="0" izz="0"/>
    </inertial>
    <collision name="EKBot__collision">
      <origin rpy="0  0  0" xyz="0  0  0"/>
      <geometry>
        <cylinder length="0.004" radius="0.006"/>
      </geometry>
    </collision>
    <visual name="EKBot__visual">
      <origin rpy="0  0  0" xyz="0  0  0"/>
      <geometry>
        <cylinder length="0.004" radius="0.006"/>
      </geometry>
    </visual>
  </link>
  <link name="EKBot__roller4w4">
    <inertial>
      <mass value="0"/>
      <origin rpy="0  0  0" xyz="0  0  0"/>
      <inertia ixx="0" ixy="0" ixz="0" iyy="0" iyz="0" izz="0"/>
    </inertial>
    <collision name="EKBot__collision">
      <origin rpy="0  0  0" xyz="0  0  0"/>
      <geometry>
        <cylinder length="0.004" radius="0.006"/>
      </geometry>
    </collision>
    <visual name="EKBot__visual">
      <origin rpy="0  0  0" xyz="0  0  0"/>
      <geometry>
        <cylinder length="0.004" radius="0.006"/>
      </geometry>
    </visual>
  </link>
  <link name="EKBot__roller5w4">
    <inertial>
      <mass value="0"/>
      <origin rpy="0  0  0" xyz="0  0  0"/>
      <inertia ixx="0" ixy="0" ixz="0" iyy="0" iyz="0" izz="0"/>
    </inertial>
    <collision name="EKBot__collision">
      <origin rpy="0  0  0" xyz="0  0  0"/>
      <geometry>
        <cylinder length="0.004" radius="0.006"/>
      </geometry>
    </collision>
    <visual name="EKBot__visual">
      <origin rpy="0  0  0" xyz="0  0  0"/>
      <geometry>
        <cylinder length="0.004" radius="0.006"/>
      </geometry>
    </visual>
  </link>
  <link name="EKBot__roller6w4">
    <inertial>
      <mass value="0"/>
      <origin rpy="0  0  0" xyz="0  0  0"/>
      <inertia ixx="0" ixy="0" ixz="0" iyy="0" iyz="0" izz="0"/>
    </inertial>
    <collision name="EKBot__collision">
      <origin rpy="0  0  0" xyz="0  0  0"/>
      <geometry>
        <cylinder length="0.004" radius="0.006"/>
      </geometry>
    </collision>
    <visual name="EKBot__visual">
      <origin rpy="0  0  0" xyz="0  0  0"/>
      <geometry>
        <cylinder length="0.004" radius="0.006"/>
      </geometry>
    </visual>
  </link>
  <link name="EKBot__roller7w4">
    <inertial>
      <mass value="0"/>
      <origin rpy="0  0  0" xyz="0  0  0"/>
      <inertia ixx="0" ixy="0" ixz="0" iyy="0" iyz="0" izz="0"/>
    </inertial>
    <collision name="EKBot__collision">
      <origin rpy="0  0  0" xyz="0  0  0"/>
      <geometry>
        <cylinder length="0.004" radius="0.006"/>
      </geometry>
    </collision>
    <visual name="EKBot__visual">
      <origin rpy="0  0  0" xyz="0  0  0"/>
      <geometry>
        <cylinder length="0.004" radius="0.006"/>
      </geometry>
    </visual>
  </link>
  <link name="EKBot__roller8w4">
    <inertial>
      <mass value="0"/>
      <origin rpy="0  0  0" xyz="0  0  0"/>
      <inertia ixx="0" ixy="0" ixz="0" iyy="0" iyz="0" izz="0"/>
    </inertial>
    <collision name="EKBot__collision">
      <origin rpy="0  0  0" xyz="0  0  0"/>
      <geometry>
        <cylinder length="0.004" radius="0.006"/>
      </geometry>
    </collision>
    <visual name="EKBot__visual">
      <origin rpy="0  0  0" xyz="0  0  0"/>
      <geometry>
        <cylinder length="0.004" radius="0.006"/>
      </geometry>
    </visual>
  </link>
  <link name="EKBot__roller9w4">
    <inertial>
      <mass value="0"/>
      <origin rpy="0  0  0" xyz="0  0  0"/>
      <inertia ixx="0" ixy="0" ixz="0" iyy="0" iyz="0" izz="0"/>
    </inertial>
    <collision name="EKBot__collision">
      <origin rpy="0  0  0" xyz="0  0  0"/>
      <geometry>
        <cylinder length="0.004" radius="0.006"/>
      </geometry>
    </collision>
    <visual name="EKBot__visual">
      <origin rpy="0  0  0" xyz="0  0  0"/>
      <geometry>
        <cylinder length="0.004" radius="0.006"/>
      </geometry>
    </visual>
  </link>
  <link name="EKBot__roller10w4">
    <inertial>
      <mass value="0"/>
      <origin rpy="0  0  0" xyz="0  0  0"/>
      <inertia ixx="0" ixy="0" ixz="0" iyy="0" iyz="0" izz="0"/>
    </inertial>
    <collision name="EKBot__collision">
      <origin rpy="0  0  0" xyz="0  0  0"/>
      <geometry>
        <cylinder length="0.004" radius="0.006"/>
      </geometry>
    </collision>
    <visual name="EKBot__visual">
      <origin rpy="0  0  0" xyz="0  0  0"/>
      <geometry>
        <cylinder length="0.004" radius="0.006"/>
      </geometry>
    </visual>
  </link>
  <link name="EKBot__roller11w4">
    <inertial>
      <mass value="0"/>
      <origin rpy="0  0  0" xyz="0  0  0"/>
      <inertia ixx="0" ixy="0" ixz="0" iyy="0" iyz="0" izz="0"/>
    </inertial>
    <collision name="EKBot__collision">
      <origin rpy="0  0  0" xyz="0  0  0"/>
      <geometry>
        <cylinder length="0.004" radius="0.006"/>
      </geometry>
    </collision>
    <visual name="EKBot__visual">
      <origin rpy="0  0  0" xyz="0  0  0"/>
      <geometry>
        <cylinder length="0.004" radius="0.006"/>
      </geometry>
    </visual>
  </link>
  <link name="EKBot__roller12w4">
    <inertial>
      <mass value="0"/>
      <origin rpy="0  0  0" xyz="0  0  0"/>
      <inertia ixx="0" ixy="0" ixz="0" iyy="0" iyz="0" izz="0"/>
    </inertial>
    <collision name="EKBot__collision">
      <origin rpy="0  0  0" xyz="0  0  0"/>
      <geometry>
        <cylinder length="0.004" radius="0.006"/>
      </geometry>
    </collision>
    <visual name="EKBot__visual">
      <origin rpy="0  0  0" xyz="0  0  0"/>
      <geometry>
        <cylinder length="0.004" radius="0.006"/>
      </geometry>
    </visual>
  </link>
  <link name="EKBot__roller13w4">
    <inertial>
      <mass value="0"/>
      <origin rpy="0  0  0" xyz="0  0  0"/>
      <inertia ixx="0" ixy="0" ixz="0" iyy="0" iyz="0" izz="0"/>
    </inertial>
    <collision name="EKBot__collision">
      <origin rpy="0  0  0" xyz="0  0  0"/>
      <geometry>
        <cylinder length="0.004" radius="0.006"/>
      </geometry>
    </collision>
    <visual name="EKBot__visual">
      <origin rpy="0  0  0" xyz="0  0  0"/>
      <geometry>
        <cylinder length="0.004" radius="0.006"/>
      </geometry>
    </visual>
  </link>
  <link name="EKBot__roller14w4">
    <inertial>
      <mass value="0"/>
      <origin rpy="0  0  0" xyz="0  0  0"/>
      <inertia ixx="0" ixy="0" ixz="0" iyy="0" iyz="0" izz="0"/>
    </inertial>
    <collision name="EKBot__collision">
      <origin rpy="0  0  0" xyz="0  0  0"/>
      <geometry>
        <cylinder length="0.004" radius="0.006"/>
      </geometry>
    </collision>
    <visual name="EKBot__visual">
      <origin rpy="0  0  0" xyz="0  0  0"/>
      <geometry>
        <cylinder length="0.004" radius="0.006"/>
      </geometry>
    </visual>
  </link>
  <link name="EKBot__roller15w4">
    <inertial>
      <mass value="0"/>
      <origin rpy="0  0  0" xyz="0  0  0"/>
      <inertia ixx="0" ixy="0" ixz="0" iyy="0" iyz="0" izz="0"/>
    </inertial>
    <collision name="EKBot__collision">
      <origin rpy="0  0  0" xyz="0  0  0"/>
      <geometry>
        <cylinder length="0.004" radius="0.006"/>
      </geometry>
    </collision>
    <visual name="EKBot__visual">
      <origin rpy="0  0  0" xyz="0  0  0"/>
      <geometry>
        <cylinder length="0.004" radius="0.006"/>
      </geometry>
    </visual>
  </link>
  <link name="EKBot__roller16w4">
    <inertial>
      <mass value="0"/>
      <origin rpy="0  0  0" xyz="0  0  0"/>
      <inertia ixx="0" ixy="0" ixz="0" iyy="0" iyz="0" izz="0"/>
    </inertial>
    <collision name="EKBot__collision">
      <origin rpy="0  0  0" xyz="0  0  0"/>
      <geometry>
        <cylinder length="0.004" radius="0.006"/>
      </geometry>
    </collision>
    <visual name="EKBot__visual">
      <origin rpy="0  0  0" xyz="0  0  0"/>
      <geometry>
        <cylinder length="0.004" radius="0.006"/>
      </geometry>
    </visual>
  </link>
  <link name="EKBot__roller17w4">
    <inertial>
      <mass value="0"/>
      <origin rpy="0  0  0" xyz="0  0  0"/>
      <inertia ixx="0" ixy="0" ixz="0" iyy="0" iyz="0" izz="0"/>
    </inertial>
    <collision name="EKBot__collision">
      <origin rpy="0  0  0" xyz="0  0  0"/>
      <geometry>
        <cylinder length="0.004" radius="0.006"/>
      </geometry>
    </collision>
    <visual name="EKBot__visual">
      <origin rpy="0  0  0" xyz="0  0  0"/>
      <geometry>
        <cylinder length="0.004" radius="0.006"/>
      </geometry>
    </visual>
  </link>
  <link name="EKBot__roller18w4">
    <inertial>
      <mass value="0"/>
      <origin rpy="0  0  0" xyz="0  0  0"/>
      <inertia ixx="0" ixy="0" ixz="0" iyy="0" iyz="0" izz="0"/>
    </inertial>
    <collision name="EKBot__collision">
      <origin rpy="0  0  0" xyz="0  0  0"/>
      <geometry>
        <cylinder length="0.004" radius="0.006"/>
      </geometry>
    </collision>
    <visual name="EKBot__visual">
      <origin rpy="0  0  0" xyz="0  0  0"/>
      <geometry>
        <cylinder length="0.004" radius="0.006"/>
      </geometry>
    </visual>
  </link>
  <link name="EKBot__roller19w4">
    <inertial>
      <mass value="0"/>
      <origin rpy="0  0  0" xyz="0  0  0"/>
      <inertia ixx="0" ixy="0" ixz="0" iyy="0" iyz="0" izz="0"/>
    </inertial>
    <collision name="EKBot__collision">
      <origin rpy="0  0  0" xyz="0  0  0"/>
      <geometry>
        <cylinder length="0.004" radius="0.006"/>
      </geometry>
    </collision>
    <visual name="EKBot__visual">
      <origin rpy="0  0  0" xyz="0  0  0"/>
      <geometry>
        <cylinder length="0.004" radius="0.006"/>
      </geometry>
    </visual>
  </link>
  <link name="EKBot__roller20w4">
    <inertial>
      <mass value="0"/>
      <origin rpy="0  0  0" xyz="0  0  0"/>
      <inertia ixx="0" ixy="0" ixz="0" iyy="0" iyz="0" izz="0"/>
    </inertial>
    <collision name="EKBot__collision">
      <origin rpy="0  0  0" xyz="0  0  0"/>
      <geometry>
        <cylinder length="0.004" radius="0.006"/>
      </geometry>
    </collision>
    <visual name="EKBot__visual">
      <origin rpy="0  0  0" xyz="0  0  0"/>
      <geometry>
        <cylinder length="0.004" radius="0.006"/>
      </geometry>
    </visual>
  </link>
  <link name="EKBot__roller21w4">
    <inertial>
      <mass value="0"/>
      <origin rpy="0  0  0" xyz="0  0  0"/>
      <inertia ixx="0" ixy="0" ixz="0" iyy="0" iyz="0" izz="0"/>
    </inertial>
    <collision name="EKBot__collision">
      <origin rpy="0  0  0" xyz="0  0  0"/>
      <geometry>
        <cylinder length="0.004" radius="0.006"/>
      </geometry>
    </collision>
    <visual name="EKBot__visual">
      <origin rpy="0  0  0" xyz="0  0  0"/>
      <geometry>
        <cylinder length="0.004" radius="0.006"/>
      </geometry>
    </visual>
  </link>
</robot>
